<?xml version="1.0"?>
<sdf version="1.7">
  <model name='windrobo'>
    <link name='base_link'>
      <inertial>
        <pose>-0.029907 -0.001148 -0.033059 0 -0 0</pose>
        <mass>19</mass>
        <inertia>
          <ixx>1.42002215</ixx>
          <ixy>-0.00391508</ixy>
          <ixz>-0.00041755</ixz>
          <iyy>1.50250178</iyy>
          <iyz>0.03239674</iyz>
          <izz>1.90699933</izz>
        </inertia>
      </inertial>
      <collision name='base_link_collision'>
        <pose>0 0 -0.18 0 -0 0</pose>
        <geometry>
          <box>
            <size>1 1 0.6</size>
          </box>
        </geometry>
      </collision>
      <collision name='base_link_fixed_joint_lump__pcb_link_collision_1'>
        <pose>-0.20228 -0.00167 -0.20679 0 -0 0</pose>
        <geometry>
          <mesh>
            <scale>1 1 1</scale>
            <uri>model://windrobo/meshes/pcb_link.STL</uri>
          </mesh>
        </geometry>
      </collision>
      <collision name='base_link_fixed_joint_lump__water_link_collision_2'>
        <pose>-0.32518 0.02883 -0.21379 0 -0 0</pose>
        <geometry>
          <mesh>
            <scale>1 1 1</scale>
            <uri>model://windrobo/meshes/water_link.STL</uri>
          </mesh>
        </geometry>
      </collision>
      <visual name='base_link_visual'>
        <pose>0 0 0 0 -0 0</pose>
        <geometry>
          <mesh>
            <scale>1 1 1</scale>
            <uri>model://windrobo/meshes/base_link.STL</uri>
          </mesh>
        </geometry>
      </visual>
      <visual name='base_link_fixed_joint_lump__pcb_link_visual_1'>
        <pose>-0.20228 -0.00167 -0.20679 0 -0 0</pose>
        <geometry>
          <mesh>
            <scale>1 1 1</scale>
            <uri>model://windrobo/meshes/pcb_link.STL</uri>
          </mesh>
        </geometry>
      </visual>
      <visual name='base_link_fixed_joint_lump__water_link_visual_2'>
        <pose>-0.32518 0.02883 -0.21379 0 -0 0</pose>
        <geometry>
          <mesh>
            <scale>1 1 1</scale>
            <uri>model://windrobo/meshes/water_link.STL</uri>
          </mesh>
        </geometry>
      </visual>
    </link>
    <link name='/imu_link'>
      <pose>0 0 0.02 0 0 0</pose>
      <inertial>
        <pose>0 0 0 0 0 0</pose>
        <mass>0.015</mass>
        <inertia>
          <ixx>1e-05</ixx>
          <ixy>0</ixy>
          <ixz>0</ixz>
          <iyy>1e-05</iyy>
          <iyz>0</iyz>
          <izz>1e-05</izz>
        </inertia>
      </inertial>
    </link>
    <joint name='/imu_joint' type='revolute'>
      <child>/imu_link</child>
      <parent>base_link</parent>
      <axis>
        <xyz>1 0 0</xyz>
        <limit>
          <lower>0</lower>
          <upper>0</upper>
          <effort>0</effort>
          <velocity>0</velocity>
        </limit>
        <dynamics>
          <spring_reference>0</spring_reference>
          <spring_stiffness>0</spring_stiffness>
        </dynamics>
        <use_parent_model_frame>1</use_parent_model_frame>
      </axis>
    </joint>
    <joint name='rotor1_joint' type='revolute'>
      <pose relative_to='base_link'>0.37584 -0.39094 0.066381 0 -0 0</pose>
      <parent>base_link</parent>
      <child>rotor1_link</child>
      <axis>
        <xyz>0 0 1</xyz>
        <limit>
          <lower>-1e+16</lower>
          <upper>1e+16</upper>
        </limit>
        <dynamics>
          <spring_reference>0</spring_reference>
          <spring_stiffness>0</spring_stiffness>
        </dynamics>
      </axis>
    </joint>
    <link name='rotor1_link'>
      <pose relative_to='rotor1_joint'>0 0 0 0 -0 0</pose>
      <inertial>
        <pose>0 -0 -0.00116 0 -0 0</pose>
        <mass>0.032</mass>
        <inertia>
          <ixx>9.75e-07</ixx>
          <ixy>0</ixy>
          <ixz>0</ixz>
          <iyy>0.000166704</iyy>
          <iyz>0</iyz>
          <izz>0.000167604</izz>
        </inertia>
      </inertial>
      <collision name='rotor1_link_collision'>
        <pose>0 0 0 0 -0 0</pose>
        <geometry>
          <mesh>
            <scale>1 1 1</scale>
            <uri>model://windrobo/meshes/rotor1_link.STL</uri>
          </mesh>
        </geometry>
      </collision>
      <visual name='rotor1_link_visual'>
        <pose>0 0 0 0 -0 0</pose>
        <geometry>
          <mesh>
            <scale>1 1 1</scale>
            <uri>model://windrobo/meshes/rotor1_link.STL</uri>
          </mesh>
        </geometry>
      </visual>
    </link>
    <joint name='rotor2_joint' type='revolute'>
      <pose relative_to='base_link'>0.38964 0.38856 0.066381 0 -0 0</pose>
      <parent>base_link</parent>
      <child>rotor2_link</child>
      <axis>
        <xyz>0 0 1</xyz>
        <limit>
          <lower>-1e+16</lower>
          <upper>1e+16</upper>
        </limit>
        <dynamics>
          <spring_reference>0</spring_reference>
          <spring_stiffness>0</spring_stiffness>
        </dynamics>
      </axis>
    </joint>
    <link name='rotor2_link'>
      <pose relative_to='rotor2_joint'>0 0 0 0 -0 0</pose>
      <inertial>
        <pose>-1e-06 0 -0.00116 0 -0 0</pose>
        <mass>0.302086</mass>
        <inertia>
          <ixx>9.75e-07</ixx>
          <ixy>0</ixy>
          <ixz>0</ixz>
          <iyy>0.000166704</iyy>
          <iyz>0</iyz>
          <izz>0.000167604</izz>
        </inertia>
      </inertial>
      <collision name='rotor2_link_collision'>
        <pose>0 0 0 0 -0 0</pose>
        <geometry>
          <mesh>
            <scale>1 1 1</scale>
            <uri>model://windrobo/meshes/rotor2_link.STL</uri>
          </mesh>
        </geometry>
      </collision>
      <visual name='rotor2_link_visual'>
        <pose>0 0 0 0 -0 0</pose>
        <geometry>
          <mesh>
            <scale>1 1 1</scale>
            <uri>model://windrobo/meshes/rotor2_link.STL</uri>
          </mesh>
        </geometry>
      </visual>
    </link>
    <joint name='rotor3_joint' type='revolute'>
      <pose relative_to='base_link'>-0.39219 0.38736 0.066381 0 -0 0</pose>
      <parent>base_link</parent>
      <child>rotor3_link</child>
      <axis>
        <xyz>0 0 1</xyz>
        <limit>
          <lower>-1e+16</lower>
          <upper>1e+16</upper>
        </limit>
        <dynamics>
          <spring_reference>0</spring_reference>
          <spring_stiffness>0</spring_stiffness>
        </dynamics>
      </axis>
    </joint>
    <link name='rotor3_link'>
      <pose relative_to='rotor3_joint'>0 0 0 0 -0 0</pose>
      <inertial>
        <pose>-0 0 -0.00116 0 -0 0</pose>
        <mass>0.032</mass>
        <inertia>
          <ixx>9.75e-07</ixx>
          <ixy>0</ixy>
          <ixz>0</ixz>
          <iyy>0.000166704</iyy>
          <iyz>0</iyz>
          <izz>0.000167604</izz>
        </inertia>
      </inertial>
      <collision name='rotor3_link_collision'>
        <pose>0 0 0 0 -0 0</pose>
        <geometry>
          <mesh>
            <scale>1 1 1</scale>
            <uri>model://windrobo/meshes/rotor3_link.STL</uri>
          </mesh>
        </geometry>
      </collision>
      <visual name='rotor3_link_visual'>
        <pose>0 0 0 0 -0 0</pose>
        <geometry>
          <mesh>
            <scale>1 1 1</scale>
            <uri>model://windrobo/meshes/rotor3_link.STL</uri>
          </mesh>
        </geometry>
      </visual>
    </link>
    <joint name='rotor4_joint' type='revolute'>
      <pose relative_to='base_link'>-0.391 -0.39209 0.066381 0 -0 0</pose>
      <parent>base_link</parent>
      <child>rotor4_link</child>
      <axis>
        <xyz>0 0 1</xyz>
        <limit>
          <lower>-1e+16</lower>
          <upper>1e+16</upper>
        </limit>
        <dynamics>
          <spring_reference>0</spring_reference>
          <spring_stiffness>0</spring_stiffness>
        </dynamics>
      </axis>
    </joint>
    <link name='rotor4_link'>
      <pose relative_to='rotor4_joint'>0 0 0 0 -0 0</pose>
      <inertial>
        <pose>0 -0 -0.00116 0 -0 0</pose>
        <mass>0.032</mass>
        <inertia>
          <ixx>9.75e-07</ixx>
          <ixy>0</ixy>
          <ixz>0</ixz>
          <iyy>0.000166704</iyy>
          <iyz>0</iyz>
          <izz>0.000167604</izz>
        </inertia>
      </inertial>
      <collision name='rotor4_link_collision'>
        <pose>0 0 0 0 -0 0</pose>
        <geometry>
          <mesh>
            <scale>1 1 1</scale>
            <uri>model://windrobo/meshes/rotor4_link.STL</uri>
          </mesh>
        </geometry>
      </collision>
      <visual name='rotor4_link_visual'>
        <pose>0 0 0 0 -0 0</pose>
        <geometry>
          <mesh>
            <scale>1 1 1</scale>
            <uri>model://windrobo/meshes/rotor4_link.STL</uri>
          </mesh>
        </geometry>
      </visual>
    </link>
    <joint name='rotor5_joint' type='revolute'>
      <pose relative_to='base_link'>0.38964 0.38856 -0.064619 0 -0 0</pose>
      <parent>base_link</parent>
      <child>rotor5_link</child>
      <axis>
        <xyz>0 0 1</xyz>
        <limit>
          <lower>-1e+16</lower>
          <upper>1e+16</upper>
        </limit>
        <dynamics>
          <spring_reference>0</spring_reference>
          <spring_stiffness>0</spring_stiffness>
        </dynamics>
      </axis>
    </joint>
    <link name='rotor5_link'>
      <pose relative_to='rotor5_joint'>0 0 0 0 -0 0</pose>
      <inertial>
        <pose>-0 0 0.00494 0 -0 0</pose>
        <mass>0.032</mass>
        <inertia>
          <ixx>9.75e-07</ixx>
          <ixy>0</ixy>
          <ixz>0</ixz>
          <iyy>0.000166704</iyy>
          <iyz>0</iyz>
          <izz>0.000167604</izz>
        </inertia>
      </inertial>
      <collision name='rotor5_link_collision'>
        <pose>0 0 0 0 -0 0</pose>
        <geometry>
          <mesh>
            <scale>1 1 1</scale>
            <uri>model://windrobo/meshes/rotor5_link.STL</uri>
          </mesh>
        </geometry>
      </collision>
      <visual name='rotor5_link_visual'>
        <pose>0 0 0 0 -0 0</pose>
        <geometry>
          <mesh>
            <scale>1 1 1</scale>
            <uri>model://windrobo/meshes/rotor5_link.STL</uri>
          </mesh>
        </geometry>
      </visual>
    </link>
    <joint name='rotor6_joint' type='revolute'>
      <pose relative_to='base_link'>0.39084 -0.3909 -0.064619 0 -0 0</pose>
      <parent>base_link</parent>
      <child>rotor6_link</child>
      <axis>
        <xyz>0 0 1</xyz>
        <limit>
          <lower>-1e+16</lower>
          <upper>1e+16</upper>
        </limit>
        <dynamics>
          <spring_reference>0</spring_reference>
          <spring_stiffness>0</spring_stiffness>
        </dynamics>
      </axis>
    </joint>
    <link name='rotor6_link'>
      <pose relative_to='rotor6_joint'>0 0 0 0 -0 0</pose>
      <inertial>
        <pose>-0 0 0.00494 0 -0 0</pose>
        <mass>0.032</mass>
        <inertia>
          <ixx>9.75e-07</ixx>
          <ixy>0</ixy>
          <ixz>0</ixz>
          <iyy>0.000166704</iyy>
          <iyz>0</iyz>
          <izz>0.000167604</izz>
        </inertia>
      </inertial>
      <collision name='rotor6_link_collision'>
        <pose>0 0 0 0 -0 0</pose>
        <geometry>
          <mesh>
            <scale>1 1 1</scale>
            <uri>model://windrobo/meshes/rotor6_link.STL</uri>
          </mesh>
        </geometry>
      </collision>
      <visual name='rotor6_link_visual'>
        <pose>0 0 0 0 -0 0</pose>
        <geometry>
          <mesh>
            <scale>1 1 1</scale>
            <uri>model://windrobo/meshes/rotor6_link.STL</uri>
          </mesh>
        </geometry>
      </visual>
    </link>
    <joint name='rotor7_joint' type='revolute'>
      <pose relative_to='base_link'>-0.391 -0.39209 -0.064619 0 -0 0</pose>
      <parent>base_link</parent>
      <child>rotor7_link</child>
      <axis>
        <xyz>0 0 1</xyz>
        <limit>
          <lower>-1e+16</lower>
          <upper>1e+16</upper>
        </limit>
        <dynamics>
          <spring_reference>0</spring_reference>
          <spring_stiffness>0</spring_stiffness>
        </dynamics>
      </axis>
    </joint>
    <link name='rotor7_link'>
      <pose relative_to='rotor7_joint'>0 0 0 0 -0 0</pose>
      <inertial>
        <pose>-0 0 0.00494 0 -0 0</pose>
        <mass>0.032</mass>
        <inertia>
          <ixx>9.75e-07</ixx>
          <ixy>0</ixy>
          <ixz>0</ixz>
          <iyy>0.000166704</iyy>
          <iyz>0</iyz>
          <izz>0.000167604</izz>
        </inertia>
      </inertial>
      <collision name='rotor7_link_collision'>
        <pose>0 0 0 0 -0 0</pose>
        <geometry>
          <mesh>
            <scale>1 1 1</scale>
            <uri>model://windrobo/meshes/rotor7_link.STL</uri>
          </mesh>
        </geometry>
      </collision>
      <visual name='rotor7_link_visual'>
        <pose>0 0 0 0 -0 0</pose>
        <geometry>
          <mesh>
            <scale>1 1 1</scale>
            <uri>model://windrobo/meshes/rotor7_link.STL</uri>
          </mesh>
        </geometry>
      </visual>
    </link>
    <joint name='rotor8_joint' type='revolute'>
      <pose relative_to='base_link'>-0.39219 0.38736 -0.064619 0 -0 0</pose>
      <parent>base_link</parent>
      <child>rotor8_link</child>
      <axis>
        <xyz>0 0 1</xyz>
        <limit>
          <lower>-1e+16</lower>
          <upper>1e+16</upper>
        </limit>
        <dynamics>
          <spring_reference>0</spring_reference>
          <spring_stiffness>0</spring_stiffness>
        </dynamics>
      </axis>
    </joint>
    <link name='rotor8_link'>
      <pose relative_to='rotor8_joint'>0 0 0 0 -0 0</pose>
      <inertial>
        <pose>1e-06 -1e-06 0.00494 0 -0 0</pose>
        <mass>0.032</mass>
        <inertia>
          <ixx>9.75e-07</ixx>
          <ixy>0</ixy>
          <ixz>0</ixz>
          <iyy>0.000166704</iyy>
          <iyz>0</iyz>
          <izz>0.000167604</izz>
        </inertia>
      </inertial>
      <collision name='rotor8_link_collision'>
        <pose>0 0 0 0 -0 0</pose>
        <geometry>
          <mesh>
            <scale>1 1 1</scale>
            <uri>model://windrobo/meshes/rotor8_link.STL</uri>
          </mesh>
        </geometry>
      </collision>
      <visual name='rotor8_link_visual'>
        <pose>0 0 0 0 -0 0</pose>
        <geometry>
          <mesh>
            <scale>1 1 1</scale>
            <uri>model://windrobo/meshes/rotor8_link.STL</uri>
          </mesh>
        </geometry>
      </visual>
    </link>
    <joint name='servo1_joint' type='prismatic'>
      <pose relative_to='base_link'>-8.2e-05 -0.001169 0 0 -0 0</pose>
      <parent>base_link</parent>
      <child>servo1_link</child>
      <axis>
        <xyz>0 0 1</xyz>
        <limit>
          <lower>-0.32271</lower>
          <upper>0</upper>
          <effort>1000</effort>
          <velocity>0</velocity>
        </limit>
        <dynamics>
          <spring_reference>0</spring_reference>
          <spring_stiffness>0</spring_stiffness>
        </dynamics>
      </axis>
    </joint>
    <link name='servo1_link'>
      <pose relative_to='servo1_joint'>0 0 0 0 -0 0</pose>
      <inertial>
        <pose>0.031107 -6.2e-05 -0.000315 0 -0 0</pose>
        <mass>0.796983</mass>
        <inertia>
          <ixx>0.00105499</ixx>
          <ixy>3.47946e-11</ixy>
          <ixz>-7.09758e-07</ixz>
          <iyy>0.000585805</iyy>
          <iyz>2.57899e-12</iyz>
          <izz>0.00112052</izz>
        </inertia>
      </inertial>
      <visual name='servo1_link_visual'>
        <pose>0 0 0 0 -0 0</pose>
        <geometry>
          <mesh>
            <scale>1 1 1</scale>
            <uri>model://windrobo/meshes/servo1_link.STL</uri>
          </mesh>
        </geometry>
      </visual>
    </link>
    <joint name='servo2_joint' type='revolute'>
      <pose relative_to='servo1_link'>0.1275 -0.000174 0 0 -0 0</pose>
      <parent>servo1_link</parent>
      <child>servo2_link</child>
      <axis>
        <xyz>0 0 1</xyz>
        <limit>
          <lower>-1.6581</lower>
          <upper>1.7453</upper>
          <effort>30</effort>
          <velocity>0</velocity>
        </limit>
        <dynamics>
          <spring_reference>0</spring_reference>
          <spring_stiffness>0</spring_stiffness>
        </dynamics>
      </axis>
    </joint>
    <link name='servo2_link'>
      <pose relative_to='servo2_joint'>0 0 0 0 -0 0</pose>
      <inertial>
        <pose>0.19592 -0.004553 -0.005563 0 -0 0</pose>
        <mass>0.90058</mass>
        <inertia>
          <ixx>0.00047839</ixx>
          <ixy>3.6874e-08</ixy>
          <ixz>5.7532e-06</ixz>
          <iyy>0.006817</iyy>
          <iyz>9.2325e-06</iyz>
          <izz>0.0066712</izz>
        </inertia>
      </inertial>
      <collision name='servo2_link_collision'>
        <pose>0 0 0 0 -0 0</pose>
        <geometry>
          <mesh>
            <scale>1 1 1</scale>
            <uri>model://windrobo/meshes/servo2_link.STL</uri>
          </mesh>
        </geometry>
      </collision>
      <visual name='servo2_link_visual'>
        <pose>0 0 0 0 -0 0</pose>
        <geometry>
          <mesh>
            <scale>1 1 1</scale>
            <uri>model://windrobo/meshes/servo2_link.STL</uri>
          </mesh>
        </geometry>
      </visual>
    </link>
    <joint name='servo3_joint' type='revolute'>
      <pose relative_to='servo2_link'>0.371 0 0 0 -0 0</pose>
      <parent>servo2_link</parent>
      <child>servo3_link</child>
      <axis>
        <xyz>0 0 1</xyz>
        <limit>
          <lower>-2.1817</lower>
          <upper>2.1817</upper>
          <effort>10</effort>
          <velocity>0</velocity>
        </limit>
        <dynamics>
          <spring_reference>0</spring_reference>
          <spring_stiffness>0</spring_stiffness>
        </dynamics>
      </axis>
    </joint>
    <link name='servo3_link'>
      <pose relative_to='servo3_joint'>0 0 0 0 -0 0</pose>
      <inertial>
        <pose>0.141621 -0.000233 -0.000661 0 -0 0</pose>
        <mass>0.136452</mass>
        <inertia>
          <ixx>3.45753e-05</ixx>
          <ixy>-5.9006e-10</ixy>
          <ixz>-6.2022e-07</ixz>
          <iyy>0.000303906</iyy>
          <iyz>8.80463e-10</iyz>
          <izz>0.000284264</izz>
        </inertia>
      </inertial>
      <collision name='servo3_link_collision'>
        <pose>0 0 0 0 -0 0</pose>
        <geometry>
          <mesh>
            <scale>1 1 1</scale>
            <uri>model://windrobo/meshes/servo3_link.STL</uri>
          </mesh>
        </geometry>
      </collision>
      <visual name='servo3_link_visual'>
        <pose>0 0 0 0 -0 0</pose>
        <geometry>
          <mesh>
            <scale>1 1 1</scale>
            <uri>model://windrobo/meshes/servo3_link.STL</uri>
          </mesh>
        </geometry>
      </visual>
    </link>
    <joint name='servo4_joint' type='revolute'>
      <pose relative_to='servo3_link'>0.32583 0 0 0 -0 0</pose>
      <parent>servo3_link</parent>
      <child>servo4_link</child>
      <axis>
        <xyz>0 0 1</xyz>
        <limit>
          <lower>-2.618</lower>
          <upper>2.618</upper>
          <effort>10</effort>
          <velocity>0</velocity>
        </limit>
        <dynamics>
          <spring_reference>0</spring_reference>
          <spring_stiffness>0</spring_stiffness>
        </dynamics>
      </axis>
    </joint>
    <link name='servo4_link'>
      <pose relative_to='servo4_joint'>0 0 0 0 -0 0</pose>
      <inertial>
        <pose>0.079649 0.002221 4e-06 0 -0 0</pose>
        <mass>0.13495</mass>
        <inertia>
          <ixx>4.0291e-05</ixx>
          <ixy>7.2111e-07</ixy>
          <ixz>-2.387e-07</ixz>
          <iyy>6.1751e-05</iyy>
          <iyz>1.1334e-10</iyz>
          <izz>6.3034e-05</izz>
        </inertia>
      </inertial>
      <collision name='servo4_link_collision'>
        <pose>0 0 0 0 -0 0</pose>
        <geometry>
          <mesh>
            <scale>1 1 1</scale>
            <uri>model://windrobo/meshes/servo4_link.STL</uri>
          </mesh>
        </geometry>
      </collision>
      <visual name='servo4_link_visual'>
        <pose>0 0 0 0 -0 0</pose>
        <geometry>
          <mesh>
            <scale>1 1 1</scale>
            <uri>model://windrobo/meshes/servo4_link.STL</uri>
          </mesh>
        </geometry>
      </visual>
    </link>
    <joint name='servo5_joint' type='revolute'>
      <pose relative_to='servo4_link'>0.1104 0.001343 0.00015 1.5708 -0 0</pose>
      <parent>servo4_link</parent>
      <child>servo5_link</child>
      <axis>
        <xyz>0 0 1</xyz>
        <limit>
          <lower>-1.8326</lower>
          <upper>1.7802</upper>
          <effort>10</effort>
          <velocity>0</velocity>
        </limit>
        <dynamics>
          <spring_reference>0</spring_reference>
          <spring_stiffness>0</spring_stiffness>
        </dynamics>
      </axis>
    </joint>
    <link name='servo5_link'>
      <pose relative_to='servo5_joint'>0 0 0 0 -0 0</pose>
      <inertial>
        <pose>0.017311 2.1e-05 0.001043 0 -0 0</pose>
        <mass>0.014339</mass>
        <inertia>
          <ixx>8.2352e-06</ixx>
          <ixy>-1.6178e-09</ixy>
          <ixz>-7.5951e-22</ixz>
          <iyy>8.9148e-06</iyy>
          <iyz>-3.6732e-22</iyz>
          <izz>2.7749e-06</izz>
        </inertia>
      </inertial>
      <collision name='servo5_link_collision'>
        <pose>0 0 0 0 -0 0</pose>
        <geometry>
          <mesh>
            <scale>1 1 1</scale>
            <uri>model://windrobo/meshes/servo5_link.STL</uri>
          </mesh>
        </geometry>
      </collision>
      <visual name='servo5_link_visual'>
        <pose>0 0 0 0 -0 0</pose>
        <geometry>
          <mesh>
            <scale>1 1 1</scale>
            <uri>model://windrobo/meshes/servo5_link.STL</uri>
          </mesh>
        </geometry>
      </visual>
    </link>
    <joint name='servo6_joint' type='revolute'>
      <pose relative_to='servo5_link'>0.0621 -0.002672 0.001043 1.5708 -0 1.5708</pose>
      <parent>servo5_link</parent>
      <child>servo6_link</child>
      <axis>
        <xyz>0 0 1</xyz>
        <limit>
          <lower>-2.0944</lower>
          <upper>2.0944</upper>
          <effort>10</effort>
          <velocity>0</velocity>
        </limit>
        <dynamics>
          <spring_reference>0</spring_reference>
          <spring_stiffness>0</spring_stiffness>
        </dynamics>
      </axis>
    </joint>
    <link name='servo6_link'>
      <pose relative_to='servo6_joint'>0 0 0 0 -0 0</pose>
      <inertial>
        <pose>-0.005163 9e-06 0.013375 0 -0 0</pose>
        <mass>0.0051803</mass>
        <inertia>
          <ixx>1.8795e-07</ixx>
          <ixy>-3.7552e-11</ixy>
          <ixz>1.1095e-11</ixz>
          <iyy>2.9754e-07</iyy>
          <iyz>2.6238e-11</iyz>
          <izz>4.439e-07</izz>
        </inertia>
      </inertial>
      <collision name='servo6_link_collision'>
        <pose>0 0 0 0 -0 0</pose>
        <geometry>
          <mesh>
            <scale>1 1 1</scale>
            <uri>model://windrobo/meshes/servo6_link.STL</uri>
          </mesh>
        </geometry>
      </collision>
      <visual name='servo6_link_visual'>
        <pose>0 0 0 0 -0 0</pose>
        <geometry>
          <mesh>
            <scale>1 1 1</scale>
            <uri>model://windrobo/meshes/servo6_link.STL</uri>
          </mesh>
        </geometry>
      </visual>
    </link>
    <joint name='servo7_joint' type='revolute'>
      <pose relative_to='servo6_link'>0.002522 0 0.039828 0.004407 -1.57079 -3.14159</pose>
      <parent>servo6_link</parent>
      <child>servo7_link</child>
      <axis>
        <xyz>0 0 1</xyz>
        <limit>
          <lower>-0.34907</lower>
          <upper>1.7977</upper>
          <effort>10</effort>
          <velocity>0</velocity>
        </limit>
        <dynamics>
          <spring_reference>0</spring_reference>
          <spring_stiffness>0</spring_stiffness>
        </dynamics>
      </axis>
    </joint>
    <link name='servo7_link'>
      <pose relative_to='servo7_joint'>0 0 0 0 -0 0</pose>
      <inertial>
        <pose>0.034068 -0.027252 0.002312 0 -0 0</pose>
        <mass>0.48232</mass>
        <inertia>
          <ixx>0.0018262</ixx>
          <ixy>-5.012e-06</ixy>
          <ixz>7.7946e-07</ixz>
          <iyy>0.001923</iyy>
          <iyz>-7.0083e-06</iyz>
          <izz>0.0001534</izz>
        </inertia>
      </inertial>
      <collision name='servo7_link_collision'>
        <pose>0 0 0 0 -0 0</pose>
        <geometry>
          <mesh>
            <scale>1 1 1</scale>
            <uri>model://windrobo/meshes/servo7_link.STL</uri>
          </mesh>
        </geometry>
      </collision>
      <visual name='servo7_link_visual'>
        <pose>0 0 0 0 -0 0</pose>
        <geometry>
          <mesh>
            <scale>1 1 1</scale>
            <uri>model://windrobo/meshes/servo7_link.STL</uri>
          </mesh>
        </geometry>
      </visual>
    </link>
    <frame name='pcb_joint' attached_to='base_link'>
      <pose>-0.20228 -0.00167 -0.20679 0 -0 0</pose>
    </frame>
    <frame name='pcb_link' attached_to='pcb_joint' />
    <frame name='water_joint' attached_to='base_link'>
      <pose>-0.32518 0.02883 -0.21379 0 -0 0</pose>
    </frame>
    <frame name='water_link' attached_to='water_joint' />
    <include>
      <uri>model://depth_camera</uri>
      <pose>0.1 0 0 0 0 0</pose>
    </include>
    <joint name="depth_camera_joint" type="revolute">
      <child>depth_camera::link</child>
      <parent>base_link</parent>
      <axis>
        <xyz>0 0 1</xyz>
        <limit>
          <upper>0</upper>
          <lower>0</lower>
        </limit>
      </axis>
    </joint>
    <!-- <link name="ultrasonic_link">
      <pose>0 0.16 0.367 0 0 -1.57</pose>
      <inertial>
        <mass>0.015</mass>
        <inertia>
          <ixx>1e-05</ixx>
          <ixy>0</ixy>
          <ixz>0</ixz>
          <iyy>1e-05</iyy>
          <iyz>0</iyz>
          <izz>1e-05</izz>
        </inertia>
      </inertial>
      <sensor name="ultrasonic" type="ray">
        <always_on>true</always_on>
        <visualize>true</visualize>
        <update_rate>150</update_rate>
        <ray>
          <scan>
            <horizontal>
              <samples>5</samples>
              <resolution>1.000000</resolution>
              <min_angle>0.000000</min_angle>
              <max_angle>0</max_angle>
            </horizontal>
          </scan>
          <range>
            <min>0.6</min>
            <max>3.5</max>
            <resolution>0.0001</resolution>
          </range>
          <noise>
            <type>gaussian</type>
            <mean>0.0</mean>
            <stddev>0.0001</stddev>
          </noise>
        </ray>
        <plugin name="ultrasonic_sensor_1" filename="libgazebo_ros_ray_sensor.so">
          <ros>
            <remapping>~/out:=ultrasonic_sensor_1</remapping>
          </ros>
          <output_type>sensor_msgs/Range</output_type>
          <radiation_type>ultrasound</radiation_type>
          <frame_name>ultrasonic_link</frame_name>
        </plugin>
      </sensor>
    </link>
    <joint name='ultrasonic_joint' type='fixed'>
      <child>ultrasonic_link</child>
      <parent>base_link</parent>
    </joint> -->
    <plugin name='rosbag' filename='libgazebo_multirotor_base_plugin.so'>
      <robotNamespace />
      <linkName>base_link</linkName>
      <rotorVelocitySlowdownSim>10</rotorVelocitySlowdownSim>
    </plugin>
    <plugin name='motor_1' filename='libgazebo_motor_model.so'>
      <robotNamespace />
      <jointName>rotor1_joint</jointName>
      <linkName>rotor1_link</linkName>
      <turningDirection>ccw</turningDirection>
      <timeConstantUp>0.0125</timeConstantUp>
      <timeConstantDown>0.025</timeConstantDown>
      <maxRotVelocity>521</maxRotVelocity>
      <motorConstant>0.0002888</motorConstant>
      <momentConstant>0.07077</momentConstant>
      <commandSubTopic>/gazebo/command/motor_speed</commandSubTopic>
      <motorNumber>0</motorNumber>
      <rotorDragCoefficient>0.000919012</rotorDragCoefficient>
      <rollingMomentCoefficient>1e-06</rollingMomentCoefficient>
      <motorSpeedPubTopic>/motor_speed/0</motorSpeedPubTopic>
      <rotorVelocitySlowdownSim>20</rotorVelocitySlowdownSim>
    </plugin>
    <plugin name='motor_2' filename='libgazebo_motor_model.so'>
      <robotNamespace />
      <jointName>rotor2_joint</jointName>
      <linkName>rotor2_link</linkName>
      <turningDirection>cw</turningDirection>
      <timeConstantUp>0.0125</timeConstantUp>
      <timeConstantDown>0.025</timeConstantDown>
      <maxRotVelocity>521</maxRotVelocity>
      <motorConstant>0.0002888</motorConstant>
      <momentConstant>0.07077</momentConstant>
      <commandSubTopic>/gazebo/command/motor_speed</commandSubTopic>
      <motorNumber>1</motorNumber>
      <rotorDragCoefficient>0.000919012</rotorDragCoefficient>
      <rollingMomentCoefficient>1e-06</rollingMomentCoefficient>
      <motorSpeedPubTopic>/motor_speed/1</motorSpeedPubTopic>
      <rotorVelocitySlowdownSim>20</rotorVelocitySlowdownSim>
    </plugin>
    <plugin name='motor_3' filename='libgazebo_motor_model.so'>
      <robotNamespace />
      <jointName>rotor3_joint</jointName>
      <linkName>rotor3_link</linkName>
      <turningDirection>ccw</turningDirection>
      <timeConstantUp>0.0125</timeConstantUp>
      <timeConstantDown>0.025</timeConstantDown>
      <maxRotVelocity>521</maxRotVelocity>
      <motorConstant>0.0002888</motorConstant>
      <momentConstant>0.07077</momentConstant>
      <commandSubTopic>/gazebo/command/motor_speed</commandSubTopic>
      <motorNumber>2</motorNumber>
      <rotorDragCoefficient>0.000919012</rotorDragCoefficient>
      <rollingMomentCoefficient>1e-06</rollingMomentCoefficient>
      <motorSpeedPubTopic>/motor_speed/2</motorSpeedPubTopic>
      <rotorVelocitySlowdownSim>20</rotorVelocitySlowdownSim>
    </plugin>
    <plugin name='motor_4' filename='libgazebo_motor_model.so'>
      <robotNamespace />
      <jointName>rotor4_joint</jointName>
      <linkName>rotor4_link</linkName>
      <turningDirection>cw</turningDirection>
      <timeConstantUp>0.0125</timeConstantUp>
      <timeConstantDown>0.025</timeConstantDown>
      <maxRotVelocity>521</maxRotVelocity>
      <motorConstant>0.0002888</motorConstant>
      <momentConstant>0.07077</momentConstant>
      <commandSubTopic>/gazebo/command/motor_speed</commandSubTopic>
      <motorNumber>3</motorNumber>
      <rotorDragCoefficient>0.000919012</rotorDragCoefficient>
      <rollingMomentCoefficient>1e-06</rollingMomentCoefficient>
      <motorSpeedPubTopic>/motor_speed/3</motorSpeedPubTopic>
      <rotorVelocitySlowdownSim>20</rotorVelocitySlowdownSim>
    </plugin>
    <plugin name='motor_5' filename='libgazebo_motor_model.so'>
      <robotNamespace />
      <jointName>rotor5_joint</jointName>
      <linkName>rotor5_link</linkName>
      <turningDirection>ccw</turningDirection>
      <timeConstantUp>0.0125</timeConstantUp>
      <timeConstantDown>0.025</timeConstantDown>
      <maxRotVelocity>521</maxRotVelocity>
      <motorConstant>0.0002888</motorConstant>
      <momentConstant>0.07077</momentConstant>
      <commandSubTopic>/gazebo/command/motor_speed</commandSubTopic>
      <motorNumber>4</motorNumber>
      <rotorDragCoefficient>0.000919012</rotorDragCoefficient>
      <rollingMomentCoefficient>1e-06</rollingMomentCoefficient>
      <motorSpeedPubTopic>/motor_speed/4</motorSpeedPubTopic>
      <rotorVelocitySlowdownSim>20</rotorVelocitySlowdownSim>
    </plugin>
    <plugin name='motor_6' filename='libgazebo_motor_model.so'>
      <robotNamespace />
      <jointName>rotor6_joint</jointName>
      <linkName>rotor6_link</linkName>
      <turningDirection>cw</turningDirection>
      <timeConstantUp>0.0125</timeConstantUp>
      <timeConstantDown>0.025</timeConstantDown>
      <maxRotVelocity>521</maxRotVelocity>
      <motorConstant>0.0002888</motorConstant>
      <momentConstant>0.07077</momentConstant>
      <commandSubTopic>/gazebo/command/motor_speed</commandSubTopic>
      <motorNumber>5</motorNumber>
      <rotorDragCoefficient>0.000919012</rotorDragCoefficient>
      <rollingMomentCoefficient>1e-06</rollingMomentCoefficient>
      <motorSpeedPubTopic>/motor_speed/5</motorSpeedPubTopic>
      <rotorVelocitySlowdownSim>20</rotorVelocitySlowdownSim>
    </plugin>
    <plugin name='motor_7' filename='libgazebo_motor_model.so'>
      <robotNamespace />
      <jointName>rotor7_joint</jointName>
      <linkName>rotor7_link</linkName>
      <turningDirection>ccw</turningDirection>
      <timeConstantUp>0.0125</timeConstantUp>
      <timeConstantDown>0.025</timeConstantDown>
      <maxRotVelocity>521</maxRotVelocity>
      <motorConstant>0.0002888</motorConstant>
      <momentConstant>0.07077</momentConstant>
      <commandSubTopic>/gazebo/command/motor_speed</commandSubTopic>
      <motorNumber>6</motorNumber>
      <rotorDragCoefficient>0.000919012</rotorDragCoefficient>
      <rollingMomentCoefficient>1e-06</rollingMomentCoefficient>
      <motorSpeedPubTopic>/motor_speed/6</motorSpeedPubTopic>
      <rotorVelocitySlowdownSim>20</rotorVelocitySlowdownSim>
    </plugin>
    <plugin name='motor_8' filename='libgazebo_motor_model.so'>
      <robotNamespace />
      <jointName>rotor8_joint</jointName>
      <linkName>rotor8_link</linkName>
      <turningDirection>cw</turningDirection>
      <timeConstantUp>0.0125</timeConstantUp>
      <timeConstantDown>0.025</timeConstantDown>
      <maxRotVelocity>521</maxRotVelocity>
      <motorConstant>0.0002888</motorConstant>
      <momentConstant>0.07077</momentConstant>
      <commandSubTopic>/gazebo/command/motor_speed</commandSubTopic>
      <motorNumber>7</motorNumber>
      <rotorDragCoefficient>0.000919012</rotorDragCoefficient>
      <rollingMomentCoefficient>1e-06</rollingMomentCoefficient>
      <motorSpeedPubTopic>/motor_speed/7</motorSpeedPubTopic>
      <rotorVelocitySlowdownSim>20</rotorVelocitySlowdownSim>
    </plugin>
    <include>
      <uri>model://gps</uri>
      <pose>0 0 0 0 0 0</pose>
      <name>gps0</name>
    </include>
    <joint name='gps0_joint' type='fixed'>
      <child>gps0::link</child>
      <parent>base_link</parent>
    </joint>
    <plugin name='groundtruth_plugin' filename='libgazebo_groundtruth_plugin.so'>
      <robotNamespace />
    </plugin>
    <plugin name='magnetometer_plugin' filename='libgazebo_magnetometer_plugin.so'>
      <robotNamespace />
      <pubRate>100</pubRate>
      <noiseDensity>0.0004</noiseDensity>
      <randomWalk>6.4e-06</randomWalk>
      <biasCorrelationTime>600</biasCorrelationTime>
      <magTopic>/mag</magTopic>
    </plugin>
    <plugin name='barometer_plugin' filename='libgazebo_barometer_plugin.so'>
      <robotNamespace />
      <pubRate>50</pubRate>
      <baroTopic>/baro</baroTopic>
      <baroDriftPaPerSec>0</baroDriftPaPerSec>
    </plugin>
    <plugin name='mavlink_interface' filename='libgazebo_mavlink_interface.so'>
      <robotNamespace />
      <imuSubTopic>/imu</imuSubTopic>
      <magSubTopic>/mag</magSubTopic>
      <baroSubTopic>/baro</baroSubTopic>
      <mavlink_addr>INADDR_ANY</mavlink_addr>
      <mavlink_tcp_port>4560</mavlink_tcp_port>
      <mavlink_udp_port>14560</mavlink_udp_port>
      <serialEnabled>0</serialEnabled>
      <serialDevice>/dev/ttyACM0</serialDevice>
      <baudRate>921600</baudRate>
      <qgc_addr>INADDR_ANY</qgc_addr>
      <qgc_udp_port>14550</qgc_udp_port>
      <sdk_addr>INADDR_ANY</sdk_addr>
      <sdk_udp_port>14540</sdk_udp_port>
      <hil_mode>0</hil_mode>
      <hil_state_level>0</hil_state_level>
      <send_vision_estimation>0</send_vision_estimation>
      <send_odometry>1</send_odometry>
      <enable_lockstep>1</enable_lockstep>
      <use_tcp>1</use_tcp>
      <motorSpeedCommandPubTopic>/gazebo/command/motor_speed</motorSpeedCommandPubTopic>
      <control_channels>
        <channel name='rotor0'>
          <input_index>0</input_index>
          <input_offset>0</input_offset>
          <input_scaling>521</input_scaling>
          <zero_position_disarmed>0</zero_position_disarmed>
          <zero_position_armed>100</zero_position_armed>
          <joint_control_type>velocity</joint_control_type>
        </channel>
        <channel name='rotor1'>
          <input_index>1</input_index>
          <input_offset>0</input_offset>
          <input_scaling>521</input_scaling>
          <zero_position_disarmed>0</zero_position_disarmed>
          <zero_position_armed>100</zero_position_armed>
          <joint_control_type>velocity</joint_control_type>
        </channel>
        <channel name='rotor2'>
          <input_index>2</input_index>
          <input_offset>0</input_offset>
          <input_scaling>521</input_scaling>
          <zero_position_disarmed>0</zero_position_disarmed>
          <zero_position_armed>100</zero_position_armed>
          <joint_control_type>velocity</joint_control_type>
        </channel>
        <channel name='rotor3'>
          <input_index>3</input_index>
          <input_offset>0</input_offset>
          <input_scaling>521</input_scaling>
          <zero_position_disarmed>0</zero_position_disarmed>
          <zero_position_armed>100</zero_position_armed>
          <joint_control_type>velocity</joint_control_type>
        </channel>
        <channel name='rotor4'>
          <input_index>4</input_index>
          <input_offset>0</input_offset>
          <input_scaling>521</input_scaling>
          <zero_position_disarmed>0</zero_position_disarmed>
          <zero_position_armed>100</zero_position_armed>
          <joint_control_type>velocity</joint_control_type>
        </channel>
        <channel name='rotor5'>
          <input_index>5</input_index>
          <input_offset>0</input_offset>
          <input_scaling>521</input_scaling>
          <zero_position_disarmed>0</zero_position_disarmed>
          <zero_position_armed>100</zero_position_armed>
          <joint_control_type>velocity</joint_control_type>
        </channel>
        <channel name='rotor6'>
          <input_index>6</input_index>
          <input_offset>0</input_offset>
          <input_scaling>521</input_scaling>
          <zero_position_disarmed>0</zero_position_disarmed>
          <zero_position_armed>100</zero_position_armed>
          <joint_control_type>velocity</joint_control_type>
        </channel>
        <channel name='rotor7'>
          <input_index>7</input_index>
          <input_offset>0</input_offset>
          <input_scaling>521</input_scaling>
          <zero_position_disarmed>0</zero_position_disarmed>
          <zero_position_armed>100</zero_position_armed>
          <joint_control_type>velocity</joint_control_type>
        </channel>
      </control_channels>
    </plugin>
    <plugin name='rotors_gazebo_imu_plugin' filename='libgazebo_imu_plugin.so'>
      <robotNamespace></robotNamespace>
      <linkName>/imu_link</linkName>
      <imuTopic>/imu</imuTopic>
      <gyroscopeNoiseDensity>0.0003394</gyroscopeNoiseDensity>
      <gyroscopeRandomWalk>3.8785e-05</gyroscopeRandomWalk>
      <gyroscopeBiasCorrelationTime>1000.0</gyroscopeBiasCorrelationTime>
      <gyroscopeTurnOnBiasSigma>0.0087</gyroscopeTurnOnBiasSigma>
      <accelerometerNoiseDensity>0.004</accelerometerNoiseDensity>
      <accelerometerRandomWalk>0.006</accelerometerRandomWalk>
      <accelerometerBiasCorrelationTime>300.0</accelerometerBiasCorrelationTime>
      <accelerometerTurnOnBiasSigma>0.196</accelerometerTurnOnBiasSigma>
    </plugin>
    <static>0</static>

    <plugin name="gazebo_ros2_control"
  filename="libgazebo_ros2_control.so">
    <parameters>/home/windrobo/windrobo/windrobo_ws/src/windrobo_controller/config/windrobo_controller.yaml</parameters>
  </plugin>

  </model>
</sdf>