<sdf version='1.7'>
  <model name='windrobo'>
    <link name='base_link'>
      <self_collide>0</self_collide>
      <inertial>
        <pose>-0.006055 0.000206 -0.102186 0 -0 0</pose>
        <mass>7.923</mass>
        <inertia>
          <ixx>0.60625540</ixx>
          <ixy>-0.00000806</ixy>
          <ixz>-0.00691153</ixz>
          <iyy>0.58352277</iyy>
          <iyz>-0.00005032</iyz>
          <izz>0.79721435</izz>
        </inertia>
      </inertial>
      <collision name='base_link_collision'>
        <pose>0 0 -0.28 0 -0 0</pose>
        <geometry>
          <box>
            <size>1 1 0.4</size>
          </box>
        </geometry>
      </collision>
      <!-- <collision name='base_link_fixed_joint_lump__propellerguar_l_link_collision_2'>
        <pose>0.399399 0.398317 0 0 -0 0</pose>
        <geometry>
          <mesh>
            <scale>1 1 1</scale>
            <uri>model://windrobo/meshes/propellerguar_l_link.STL</uri>
          </mesh>
        </geometry>
      </collision>
      <collision name='base_link_fixed_joint_lump__propellerguar_r_link_collision_3'>
        <pose>0.399399 -0.39808 0 0 -0 0</pose>
        <geometry>
          <mesh>
            <scale>1 1 1</scale>
            <uri>model://windrobo/meshes/propellerguar_r_link.STL</uri>
          </mesh>
        </geometry>
      </collision> -->
      <visual name='base_link_visual'>
        <pose>0 0 0 0 -0 0</pose>
        <geometry>
          <mesh>
            <scale>1 1 1</scale>
            <uri>model://windrobo/meshes/base_link.dae</uri>
          </mesh>
        </geometry>
      </visual>
      <!-- <visual name='base_link_fixed_joint_lump__propellerguar_l_link_visual_2'>
        <pose>0.399399 0.398317 0 0 -0 0</pose>
        <geometry>
          <mesh>
            <scale>1 1 1</scale>
            <uri>model://windrobo/meshes/propellerguar_l_link.STL</uri>
          </mesh>
        </geometry>
      </visual>
      <visual name='base_link_fixed_joint_lump__propellerguar_r_link_visual_3'>
        <pose>0.399399 -0.39808 0 0 -0 0</pose>
        <geometry>
          <mesh>
            <scale>1 1 1</scale>
            <uri>model://windrobo/meshes/propellerguar_r_link.STL</uri>
          </mesh>
        </geometry>
      </visual> -->
    </link>

    <!-- BATTERY -->
    <joint name="battery_joint" type="fixed">
      <pose>0.010982 0 0.094513 0 -0 0</pose>
      <parent>base_link</parent>
      <child>battery_link</child>
    </joint>
    <link name="battery_link">
      <pose>0 0 0 0 0 0</pose>
      <inertial>
        <mass>5.088</mass>
        <inertia>
          <ixx>0.01317976</ixx>
          <ixy>-0.00000000</ixy>
          <ixz>-0.00000000</ixz>
          <iyy>0.02330258</iyy>
          <iyz>-0.00000008</iyz>
          <izz>0.02883593</izz>
        </inertia>
      </inertial>
      <visual name="battery_visual">
        <pose>0.010982 0 0.094513 0 -0 0</pose>
        <geometry>
          <mesh>
            <scale>1 1 1</scale>
            <uri>model://windrobo/meshes/battery_link.dae</uri>
          </mesh>
        </geometry>
      </visual>
      <collision name="battery_collision">
        <pose>0.010982 0 0.094513 0 -0 0</pose>
        <geometry>
          <box>
            <size>0.01 0.01 0.01</size>
          </box>
        </geometry>
      </collision>
    </link>

    <!-- CAMERA -->
    <joint name="camera_joint" type="fixed">
      <pose>0.191275 0.00077 0.139513 0 -0 0</pose>
      <parent>base_link</parent>
      <child>camera_link</child>
    </joint>
    <link name="camera_link">
      <pose>0 0 0 0 0 0</pose>
      <inertial>
        <mass>0.115</mass>
        <inertia>
          <ixx>0.00009587</ixx>
          <ixy>-0.00000000</ixy>
          <ixz>-0.00000081</ixz>
          <iyy>0.00003102</iyy>
          <iyz>0.00000000</iyz>
          <izz>0.00008268</izz>
        </inertia>
      </inertial>
      <visual name="camera_visual">
        <pose>0.191275 0.00077 0.139513 0 -0 0</pose>
        <geometry>
          <mesh>
            <scale>1 1 1</scale>
            <uri>model://windrobo/meshes/camera_link.dae</uri>
          </mesh>
        </geometry>
      </visual>
      <collision name="camera_collision">
        <pose>0.191275 0.00077 0.139513 0 -0 0</pose>
        <geometry>
          <box>
            <size>0.01 0.01 0.01</size>
          </box>
        </geometry>
      </collision>
      <sensor name='camera' type='camera'>
        <visualize>1</visualize>
        <update_rate>10</update_rate>
        <camera>
          <horizontal_fov>1.20428</horizontal_fov>
          <image>
            <format>R8G8B8</format>
            <width>1280</width>
            <height>720</height>
          </image>
          <clip>
            <near>0.05</near>
            <far>100</far>
          </clip>
        </camera>
        <!-- <camera>
          <horizontal_fov>1.20428</horizontal_fov>
          <image>
            <format>R8G8B8</format>
            <width>1280</width>
            <height>720</height>
          </image>
          <clip>
            <near>0.05</near>
            <far>100</far>
          </clip>
        </camera> -->
        <plugin name='camera_controller' filename='libgazebo_ros_camera.so'>
          <frame_name>camera_link_optical</frame_name>
        </plugin>
        <pose>0.191275 0 0.139513 0 -0 0</pose>
      </sensor>
    </link>

    <!-- SONAR / ULTRASONIC -->
    <joint name="sonar_joint" type="fixed">
      <pose>0.158375 0.00077 0.055778 0 -0 0</pose>
      <parent>base_link</parent>
      <child>sonar_link</child>
    </joint>
    <link name="sonar_link">
      <pose>0 0 0 0 0 0</pose>
      <inertial>
        <mass>0.057</mass>
        <inertia>
          <ixx>0.00001089</ixx>
          <ixy>0.00000003</ixy>
          <ixz>0.00000002</ixz>
          <iyy>0.00002491</iyy>
          <iyz>-0.00000000</iyz>
          <izz>0.00002489</izz>
        </inertia>
      </inertial>
      <visual name="sonar_visual">
        <pose>0.158375 0.00077 0.055778 0 -0 0</pose>
        <geometry>
          <mesh>
            <scale>1 1 1</scale>
            <uri>model://windrobo/meshes/sonar_link.dae</uri>
          </mesh>
        </geometry>
      </visual>
      <collision name="sonar_collision">
        <pose>0.158375 0.00077 0.055778 0 -0 0</pose>
        <geometry>
          <box>
            <size>0.01 0.01 0.01</size>
          </box>
        </geometry>
      </collision>
      <sensor name="ultrasonic" type="ray">
        <pose>0.158375 0.00077 0.055778 0 -0 0</pose>
        <visualize>true</visualize>
        <update_rate>50</update_rate>
        <ray>
          <scan>
            <horizontal>
              <samples>10</samples>
              <resolution>1</resolution>
              <min_angle>-0.00174533</min_angle>
              <max_angle>0.00174533</max_angle>
            </horizontal>
            <vertical>
              <samples>10</samples>
              <resolution>1</resolution>
              <min_angle>-0.00174533</min_angle>
              <max_angle>0.00174533</max_angle>
            </vertical>
          </scan>
          <range>
            <min>0.05</min>
            <max>10</max>
            <resolution>0.001</resolution>
          </range>
        </ray>
        <plugin filename="libgazebo_ros_ray_sensor.so" name="ultrasonic">
          <gaussianNoise>0.005</gaussianNoise>
          <alwaysOn>true</alwaysOn>
          <updateRate>50</updateRate>
          <topicName>sensor/ultrasonic</topicName>
          <frameName>sonar_link</frameName>
          <radiation>ultrasound</radiation>
          <fov>0.2967</fov>
          <output_type>sensor_msgs/Range</output_type>
        </plugin>
      </sensor>
    </link>

    <!-- PCB BOX -->
    <joint name="pcb_joint" type="fixed">
      <pose>-0.220619 0 -0.192487 0 -0 0</pose>
      <parent>base_link</parent>
      <child>pcb_link</child>
    </joint>
    <link name="pcb_link">
      <pose>0 0 0 0 0 0</pose>
      <inertial>
        <mass>1</mass>
        <inertia>
          <ixx>0.005552087</ixx>
          <ixy>-0.00000000</ixy>
          <ixz>-0.00000000</ixz>
          <iyy>0.0033208</iyy>
          <iyz>0.00000000</iyz>
          <izz>0.00316875</izz>
        </inertia>
      </inertial>
      <visual name="pcb_visual">
        <pose>-0.220619 0 -0.192487 0 -0 0</pose>
        <geometry>
          <mesh>
            <scale>1 1 1</scale>
            <uri>model://windrobo/meshes/pcb_link.dae</uri>
          </mesh>
        </geometry>
      </visual>
      <collision name="pcb_collision">
        <pose>-0.220619 0 -0.192487 0 -0 0</pose>
        <geometry>
          <box>
            <size>0.01 0.01 0.01</size>
          </box>
        </geometry>
      </collision>
    </link>

    <!-- WATER -->
    <joint name="water_joint" type="fixed">
      <pose>-0.325119 0 -0.204987 0 -0 0</pose>
      <parent>base_link</parent>
      <child>water_link</child>
    </joint>
    <link name="water_link">
      <pose>0 0 0 0 0 0</pose>
      <inertial>
        <mass>1.254</mass>
        <inertia>
          <ixx>0.00692328</ixx>
          <ixy>-0.00000000</ixy>
          <ixz>-0.00000000</ixz>
          <iyy>0.00603683</iyy>
          <iyz>-0.00000003</iyz>
          <izz>0.00409153</izz>
        </inertia>
      </inertial>
      <visual name="water_visual">
        <pose>-0.325119 0 -0.204987 0 -0 0</pose>
        <geometry>
          <mesh>
            <scale>1 1 1</scale>
            <uri>model://windrobo/meshes/water_link.dae</uri>
          </mesh>
        </geometry>
      </visual>
      <collision name="water_collision">
        <pose>-0.325119 0 -0.204987 0 -0 0</pose>
        <geometry>
          <box>
            <size>0.01 0.01 0.01</size>
          </box>
        </geometry>
      </collision>
    </link>

    <link name='/imu_link'>
      <pose>0 0 0.02 0 0 0</pose>
      <inertial>
        <pose>0 0 0 0 0 0</pose>
        <mass>0.015</mass>
        <inertia>
          <ixx>1e-05</ixx>
          <ixy>0</ixy>
          <ixz>0</ixz>
          <iyy>1e-05</iyy>
          <iyz>0</iyz>
          <izz>1e-05</izz>
        </inertia>
      </inertial>
    </link>
    <joint name='/imu_joint' type='revolute'>
      <child>/imu_link</child>
      <parent>base_link</parent>
      <axis>
        <xyz>1 0 0</xyz>
        <limit>
          <lower>0</lower>
          <upper>0</upper>
          <effort>0</effort>
          <velocity>0</velocity>
        </limit>
        <dynamics>
          <spring_reference>0</spring_reference>
          <spring_stiffness>0</spring_stiffness>
        </dynamics>
        <use_parent_model_frame>1</use_parent_model_frame>
      </axis>
    </joint>

    <!-- ROTORS -->

    <joint name='rotor1_joint' type='revolute'>
      <pose relative_to='base_link'>0.37584 -0.39094 0.066381 0 -0 0</pose>
      <parent>base_link</parent>
      <child>rotor1_link</child>
      <axis>
        <xyz>0 0 1</xyz>
        <limit>
          <lower>-1e+16</lower>
          <upper>1e+16</upper>
          <effort>0</effort>
          <velocity>0</velocity>
        </limit>
        <dynamics>
          <spring_reference>0</spring_reference>
          <spring_stiffness>0</spring_stiffness>
        </dynamics>
      </axis>
    </joint>
    <link name='rotor1_link'>
      <pose relative_to='rotor1_joint'>0 0 0 0 -0 0</pose>
      <inertial>
        <pose>0 -0 -0.00116 0 -0 0</pose>
        <mass>0.816</mass>
        <inertia>
          <ixx>0.00044892</ixx>
          <ixy>-0.00045680</ixy>
          <ixz>-0.00000002</ixz>
          <iyy>0.01453926</iyy>
          <iyz>-0.00000000</iyz>
          <izz>0.01478718</izz>
        </inertia>
      </inertial>
      <!-- <collision name='rotor1_link_collision'>
        <pose>0 0 0 0 -0 0</pose>
        <geometry>
          <mesh>
            <scale>1 1 1</scale>
            <uri>model://windrobo/meshes/rotor1_link.STL</uri>
          </mesh>
        </geometry>
      </collision> -->
      <visual name='rotor1_link_visual'>
        <pose>0 0 0 0 -0 0</pose>
        <geometry>
          <mesh>
            <scale>1 1 1</scale>
            <uri>model://windrobo/meshes/rotor_ccw_link.dae</uri>
          </mesh>
        </geometry>
      </visual>
    </link>
    <joint name='rotor2_joint' type='revolute'>
      <pose relative_to='base_link'>0.38964 0.38856 0.066381 0 -0 0</pose>
      <parent>base_link</parent>
      <child>rotor2_link</child>
      <axis>
        <xyz>0 0 1</xyz>
        <limit>
          <lower>-1e+16</lower>
          <upper>1e+16</upper>
          <effort>0</effort>
          <velocity>0</velocity>
        </limit>
        <dynamics>
          <spring_reference>0</spring_reference>
          <spring_stiffness>0</spring_stiffness>
        </dynamics>
      </axis>
    </joint>
    <link name='rotor2_link'>
      <pose relative_to='rotor2_joint'>0 0 0 0 -0 0</pose>
      <inertial>
        <pose>0 -0 -0.00116 0 -0 0</pose>
        <mass>0.816</mass>
        <inertia>
          <ixx>0.00044892</ixx>
          <ixy>-0.00045680</ixy>
          <ixz>-0.00000002</ixz>
          <iyy>0.01453926</iyy>
          <iyz>-0.00000000</iyz>
          <izz>0.01478718</izz>
        </inertia>
      </inertial>
      <!-- <collision name='rotor2_link_collision'>
        <pose>0 0 0 0 -0 0</pose>
        <geometry>
          <mesh>
            <scale>1 1 1</scale>
            <uri>model://windrobo/meshes/rotor2_link.STL</uri>
          </mesh>
        </geometry>
      </collision> -->
      <visual name='rotor2_link_visual'>
        <pose>0 0 0 0 -0 0</pose>
        <geometry>
          <mesh>
            <scale>1 1 1</scale>
            <uri>model://windrobo/meshes/rotor_cw_link.dae</uri>
          </mesh>
        </geometry>
      </visual>
    </link>
    <joint name='rotor3_joint' type='revolute'>
      <pose relative_to='base_link'>-0.39219 0.38736 0.066381 0 -0 0</pose>
      <parent>base_link</parent>
      <child>rotor3_link</child>
      <axis>
        <xyz>0 0 1</xyz>
        <limit>
          <lower>-1e+16</lower>
          <upper>1e+16</upper>
          <effort>0</effort>
          <velocity>0</velocity>
        </limit>
        <dynamics>
          <spring_reference>0</spring_reference>
          <spring_stiffness>0</spring_stiffness>
        </dynamics>
      </axis>
    </joint>
    <link name='rotor3_link'>
      <pose relative_to='rotor3_joint'>0 0 0 0 -0 0</pose>
      <inertial>
        <pose>0 -0 -0.00116 0 -0 0</pose>
        <mass>0.816</mass>
        <inertia>
          <ixx>0.00044892</ixx>
          <ixy>-0.00045680</ixy>
          <ixz>-0.00000002</ixz>
          <iyy>0.01453926</iyy>
          <iyz>-0.00000000</iyz>
          <izz>0.01478718</izz>
        </inertia>
      </inertial>
      <!-- <collision name='rotor3_link_collision'>
        <pose>0 0 0 0 -0 0</pose>
        <geometry>
          <mesh>
            <scale>1 1 1</scale>
            <uri>model://windrobo/meshes/rotor3_link.STL</uri>
          </mesh>
        </geometry>
      </collision> -->
      <visual name='rotor3_link_visual'>
        <pose>0 0 0 0 -0 0</pose>
        <geometry>
          <mesh>
            <scale>1 1 1</scale>
            <uri>model://windrobo/meshes/rotor_ccw_link.dae</uri>
          </mesh>
        </geometry>
      </visual>
    </link>
    <joint name='rotor4_joint' type='revolute'>
      <pose relative_to='base_link'>-0.391 -0.39209 0.066381 0 -0 0</pose>
      <parent>base_link</parent>
      <child>rotor4_link</child>
      <axis>
        <xyz>0 0 1</xyz>
        <limit>
          <lower>-1e+16</lower>
          <upper>1e+16</upper>
          <effort>0</effort>
          <velocity>0</velocity>
        </limit>
        <dynamics>
          <spring_reference>0</spring_reference>
          <spring_stiffness>0</spring_stiffness>
        </dynamics>
      </axis>
    </joint>
    <link name='rotor4_link'>
      <pose relative_to='rotor4_joint'>0 0 0 0 -0 0</pose>
      <inertial>
        <pose>0 -0 -0.00116 0 -0 0</pose>
        <mass>0.816</mass>
        <inertia>
          <ixx>0.00044892</ixx>
          <ixy>-0.00045680</ixy>
          <ixz>-0.00000002</ixz>
          <iyy>0.01453926</iyy>
          <iyz>-0.00000000</iyz>
          <izz>0.01478718</izz>
        </inertia>
      </inertial>
      <!-- <collision name='rotor4_link_collision'>
        <pose>0 0 0 0 -0 0</pose>
        <geometry>
          <mesh>
            <scale>1 1 1</scale>
            <uri>model://windrobo/meshes/rotor4_link.STL</uri>
          </mesh>
        </geometry>
      </collision> -->
      <visual name='rotor4_link_visual'>
        <pose>0 0 0 0 -0 0</pose>
        <geometry>
          <mesh>
            <scale>1 1 1</scale>
            <uri>model://windrobo/meshes/rotor_cw_link.dae</uri>
          </mesh>
        </geometry>
      </visual>
    </link>
    <joint name='rotor5_joint' type='revolute'>
      <pose relative_to='base_link'>0.38964 0.38856 -0.064619 0 -0 0</pose>
      <parent>base_link</parent>
      <child>rotor5_link</child>
      <axis>
        <xyz>0 0 1</xyz>
        <limit>
          <lower>-1e+16</lower>
          <upper>1e+16</upper>
          <effort>0</effort>
          <velocity>0</velocity>
        </limit>
        <dynamics>
          <spring_reference>0</spring_reference>
          <spring_stiffness>0</spring_stiffness>
        </dynamics>
      </axis>
    </joint>
    <link name='rotor5_link'>
      <pose relative_to='rotor5_joint'>0 0 0 0 -0 0</pose>
      <inertial>
        <pose>0 -0 -0.00116 0 -0 0</pose>
        <mass>0.816</mass>
        <inertia>
          <ixx>0.00044892</ixx>
          <ixy>-0.00045680</ixy>
          <ixz>-0.00000002</ixz>
          <iyy>0.01453926</iyy>
          <iyz>-0.00000000</iyz>
          <izz>0.01478718</izz>
        </inertia>
      </inertial>
      <!-- <collision name='rotor5_link_collision'>
        <pose>0 0 0 0 -0 0</pose>
        <geometry>
          <mesh>
            <scale>1 1 1</scale>
            <uri>model://windrobo/meshes/rotor5_link.STL</uri>
          </mesh>
        </geometry>
      </collision> -->
      <visual name='rotor5_link_visual'>
        <pose>0 0 0 3.1415 -0 0</pose>
        <geometry>
          <mesh>
            <scale>1 1 1</scale>
            <uri>model://windrobo/meshes/rotor_ccw_link.dae</uri>
          </mesh>
        </geometry>
      </visual>
    </link>
    <joint name='rotor6_joint' type='revolute'>
      <pose relative_to='base_link'>0.39084 -0.3909 -0.064619 0 -0 0</pose>
      <parent>base_link</parent>
      <child>rotor6_link</child>
      <axis>
        <xyz>0 0 1</xyz>
        <limit>
          <lower>-1e+16</lower>
          <upper>1e+16</upper>
          <effort>0</effort>
          <velocity>0</velocity>
        </limit>
        <dynamics>
          <spring_reference>0</spring_reference>
          <spring_stiffness>0</spring_stiffness>
        </dynamics>
      </axis>
    </joint>
    <link name='rotor6_link'>
      <pose relative_to='rotor6_joint'>0 0 0 0 -0 0</pose>
      <inertial>
        <pose>0 -0 -0.00116 0 -0 0</pose>
        <mass>0.816</mass>
        <inertia>
          <ixx>0.00044892</ixx>
          <ixy>-0.00045680</ixy>
          <ixz>-0.00000002</ixz>
          <iyy>0.01453926</iyy>
          <iyz>-0.00000000</iyz>
          <izz>0.01478718</izz>
        </inertia>
      </inertial>
      <!-- <collision name='rotor6_link_collision'>
        <pose>0 0 0 0 -0 0</pose>
        <geometry>
          <mesh>
            <scale>1 1 1</scale>
            <uri>model://windrobo/meshes/rotor6_link.STL</uri>
          </mesh>
        </geometry>
      </collision> -->
      <visual name='rotor6_link_visual'>
        <pose>0 0 0 3.1415 -0 0</pose>
        <geometry>
          <mesh>
            <scale>1 1 1</scale>
            <uri>model://windrobo/meshes/rotor_cw_link.dae</uri>
          </mesh>
        </geometry>
      </visual>
    </link>
    <joint name='rotor7_joint' type='revolute'>
      <pose relative_to='base_link'>-0.391 -0.39209 -0.064619 0 -0 0</pose>
      <parent>base_link</parent>
      <child>rotor7_link</child>
      <axis>
        <xyz>0 0 1</xyz>
        <limit>
          <lower>-1e+16</lower>
          <upper>1e+16</upper>
          <effort>0</effort>
          <velocity>0</velocity>
        </limit>
        <dynamics>
          <spring_reference>0</spring_reference>
          <spring_stiffness>0</spring_stiffness>
        </dynamics>
      </axis>
    </joint>
    <link name='rotor7_link'>
      <pose relative_to='rotor7_joint'>0 0 0 0 -0 0</pose>
      <inertial>
        <pose>0 -0 -0.00116 0 -0 0</pose>
        <mass>0.816</mass>
        <inertia>
          <ixx>0.00044892</ixx>
          <ixy>-0.00045680</ixy>
          <ixz>-0.00000002</ixz>
          <iyy>0.01453926</iyy>
          <iyz>-0.00000000</iyz>
          <izz>0.01478718</izz>
        </inertia>
      </inertial>
      <!-- <collision name='rotor7_link_collision'>
        <pose>0 0 0 0 -0 0</pose>
        <geometry>
          <mesh>
            <scale>1 1 1</scale>
            <uri>model://windrobo/meshes/rotor7_link.STL</uri>
          </mesh>
        </geometry>
      </collision> -->
      <visual name='rotor7_link_visual'>
        <pose>0 0 0 3.1415 -0 0</pose>
        <geometry>
          <mesh>
            <scale>1 1 1</scale>
            <uri>model://windrobo/meshes/rotor_ccw_link.dae</uri>
          </mesh>
        </geometry>
      </visual>
    </link>
    <joint name='rotor8_joint' type='revolute'>
      <pose relative_to='base_link'>-0.39219 0.38736 -0.064619 0 -0 0</pose>
      <parent>base_link</parent>
      <child>rotor8_link</child>
      <axis>
        <xyz>0 0 1</xyz>
        <limit>
          <lower>-1e+16</lower>
          <upper>1e+16</upper>
          <effort>0</effort>
          <velocity>0</velocity>
        </limit>
        <dynamics>
          <spring_reference>0</spring_reference>
          <spring_stiffness>0</spring_stiffness>
        </dynamics>
      </axis>
    </joint>
    <link name='rotor8_link'>
      <pose relative_to='rotor8_joint'>0 0 0 0 -0 0</pose>
      <inertial>
        <pose>0 -0 -0.00116 0 -0 0</pose>
        <mass>0.816</mass>
        <inertia>
          <ixx>0.00044892</ixx>
          <ixy>-0.00045680</ixy>
          <ixz>-0.00000002</ixz>
          <iyy>0.01453926</iyy>
          <iyz>-0.00000000</iyz>
          <izz>0.01478718</izz>
        </inertia>
      </inertial>
      <!-- <collision name='rotor8_link_collision'>
        <pose>0 0 0 0 -0 0</pose>
        <geometry>
          <mesh>
            <scale>1 1 1</scale>
            <uri>model://windrobo/meshes/rotor8_link.STL</uri>
          </mesh>
        </geometry>
      </collision> -->
      <visual name='rotor8_link_visual'>
        <pose>0 0 0 3.1415 -0 0</pose>
        <geometry>
          <mesh>
            <scale>1 1 1</scale>
            <uri>model://windrobo/meshes/rotor_cw_link.dae</uri>
          </mesh>
        </geometry>
      </visual>
    </link>

    <!-- ROBOTIC ARM -->

    <joint name='servo1_joint' type='prismatic'>
      <pose relative_to='base_link'>0 0 0 0 0 0</pose>
      <parent>base_link</parent>
      <child>servo1_link</child>
      <axis>
        <xyz>0 0 1</xyz>
        <limit>
          <lower>-0.28388</lower>
          <upper>-0.1838</upper>
          <effort>1000</effort>
          <velocity>0</velocity>
        </limit>
        <dynamics>
          <spring_reference>0</spring_reference>
          <damping>30</damping> <!--10-->
          <friction>300</friction>
          <spring_stiffness>0.0</spring_stiffness>
        </dynamics>
      </axis>
    </joint>
    <link name='servo1_link'>
      <pose relative_to='servo1_joint'>0 0 0 0 -0 0</pose>
      <inertial>
        <pose>0.040411 0.00012 -0.000562 0 -0 0</pose>
        <mass>1.257</mass>
        <inertia>
          <ixx>0.00898453</ixx>
          <ixy>-0.00000721</ixy>
          <ixz>0.00000146</ixz>
          <iyy>0.00526754</iyy>
          <iyz>0.00000299</iyz>
          <izz>0.00648677</izz>
        </inertia>
      </inertial>
      <!-- <collision name='servo1_link_collision'>
        <pose>0 0 0 0 -0 0</pose>
        <geometry>
          <mesh>
            <scale>1 1 1</scale>
            <uri>model://windrobo/meshes/servo1_link.STL</uri>
          </mesh>
        </geometry>
      </collision> -->
      <visual name='servo1_link_visual'>
        <pose>0 0 0 0 -0 0</pose>
        <geometry>
          <mesh>
            <scale>1 1 1</scale>
            <uri>model://windrobo/meshes/servo1_link.dae</uri>
          </mesh>
        </geometry>
      </visual>
    </link>
    <joint name='servo2_joint' type='revolute'>
      <pose relative_to='servo1_link'>0.1275 0.00017434 0 0 -0 0</pose>
      <parent>servo1_link</parent>
      <child>servo2_link</child>
      <axis>
        <xyz>0 0 1</xyz>
        <limit>
          <lower>-1.74</lower>
          <upper>1.74</upper>
          <effort>30</effort>
          <velocity>1</velocity>
        </limit>
        <dynamics>
          <spring_reference>0</spring_reference>
          <damping>6</damping>
          <friction>2.0</friction>
          <spring_stiffness>0.0</spring_stiffness>
        </dynamics>
      </axis>
    </joint>
    <link name='servo2_link'>
      <pose relative_to='servo2_joint'>0 0 0 0 0 0</pose>
      <inertial>
        <pose>0.198455 -0.003678 -0.006391 0 -0 0</pose>
        <mass>1.17</mass>
        <inertia>
          <ixx>0.00199208</ixx>
          <ixy>0.00000158</ixy>
          <ixz>-0.00006783</ixz>
          <iyy>0.01532883</iyy>
          <iyz>0.00005473</iyz>
          <izz>0.01400285</izz>
        </inertia>
      </inertial>
      <!-- <collision name='servo2_link_collision'>
        <pose>0 0 0 0 -0 0</pose>
        <geometry>
          <mesh>
            <scale>1 1 1</scale>
            <uri>model://windrobo/meshes/servo2_link.STL</uri>
          </mesh>
        </geometry>
      </collision> -->
      <visual name='servo2_link_visual'>
        <pose>0 0 0 0 -0 0</pose>
        <geometry>
          <mesh>
            <scale>1 1 1</scale>
            <uri>model://windrobo/meshes/servo2_link.dae</uri>
          </mesh>
        </geometry>
      </visual>
    </link>
    <joint name='servo3_joint' type='revolute'>
      <pose relative_to='servo2_link'>0.371 0 0 0 -0 0</pose>
      <parent>servo2_link</parent>
      <child>servo3_link</child>
      <axis>
        <xyz>0 0 1</xyz>
        <limit>
          <lower>-2.1817</lower>
          <upper>2.1817</upper>
          <effort>16</effort>
          <velocity>2</velocity>
        </limit>
        <dynamics>
          <spring_reference>0</spring_reference>
          <damping>1.0</damping>
          <friction>2.0</friction>
          <spring_stiffness>0.0</spring_stiffness> <!--1.0-->
        </dynamics>
      </axis>
    </joint>
    <link name='servo3_link'>
      <pose relative_to='servo3_joint'>0 0 0 0 -0 0</pose>
      <inertial>
        <pose>0.141621 -0.000233 -0.000661 0 -0 0</pose>
        <mass>0.271</mass>
        <inertia>
          <ixx>0.00018960</ixx>
          <ixy>-0.00000499</ixy>
          <ixz>0.00001706</ixz>
          <iyy>0.00376356</iyy>
          <iyz>0.00000003</iyz>
          <izz>0.00364405</izz>
        </inertia>
      </inertial>
      <!-- <collision name='servo3_link_collision'>
        <pose>0 0 0 0 -0 0</pose>
        <geometry>
          <mesh>
            <scale>1 1 1</scale>
            <uri>model://windrobo/meshes/servo3_link.STL</uri>
          </mesh>
        </geometry>
      </collision> -->
      <visual name='servo3_link_visual'>
        <pose>0 0 0 0 -0 0</pose>
        <geometry>
          <mesh>
            <scale>1 1 1</scale>
            <uri>model://windrobo/meshes/servo3_link.dae</uri>
          </mesh>
        </geometry>
      </visual>
    </link>
    <joint name='servo4_joint' type='revolute'>
      <pose relative_to='servo3_link'>0.35883 0.001 0 0 -0 0</pose>
      <parent>servo3_link</parent>
      <child>servo4_link</child>
      <axis>
        <xyz>0 0 1</xyz>
        <limit>
          <lower>-1.57</lower>
          <upper>2.51</upper>
          <effort>15</effort>
          <velocity>2</velocity>
        </limit>
        <dynamics>
          <spring_reference>0</spring_reference>
          <damping>1.0</damping>
          <friction>2.0</friction>
          <spring_stiffness>0</spring_stiffness> <!--1.0-->
        </dynamics>
      </axis>
    </joint>
    <link name='servo4_link'>
      <pose relative_to='servo4_joint'>0 0 0 0 -0 0</pose>
      <inertial>
        <pose>0.07885 0.001552 -0.000618 0 -0 0</pose>
        <mass>0.201</mass>
        <inertia>
          <ixx>0.00010275</ixx>
          <ixy>0.00000142</ixy>
          <ixz>0.00000000</ixz>
          <iyy>0.00033858</iyy>
          <iyz>0.00000000</iyz>
          <izz>0.00031622</izz>
        </inertia>
      </inertial>
      <!-- <collision name='servo4_link_collision'>
        <pose>0 0 0 0 -0 0</pose>
        <geometry>
          <mesh>
            <scale>1 1 1</scale>
            <uri>model://windrobo/meshes/servo4_link.STL</uri>
          </mesh>
        </geometry>
      </collision> -->
      <visual name='servo4_link_visual'>
        <pose>0 0 0 0 -0 0</pose>
        <geometry>
          <mesh>
            <scale>1 1 1</scale>
            <uri>model://windrobo/meshes/servo4_link.dae</uri>
          </mesh>
        </geometry>
      </visual>
    </link>
    <joint name='servo5_joint' type='revolute'>
      <pose relative_to='servo4_link'>0.11763 -0.001293 -0.000725 1.5708 -0 0</pose>
      <parent>servo4_link</parent>
      <child>servo5_link</child>
      <axis>
        <xyz>0 0 1</xyz>
        <limit>
          <lower>-1.85</lower>
          <upper>1.78</upper>
          <effort>11</effort>
          <velocity>2</velocity>
        </limit>
        <dynamics>
          <spring_reference>0</spring_reference>
          <!-- <damping>1.0</damping>
          <friction>2.0</friction> -->
          <damping>0.2</damping>
          <friction>0.1</friction>
          <spring_stiffness>0.0</spring_stiffness> <!--1.0-->
        </dynamics>
      </axis>
    </joint>
    <link name='servo5_link'>
      <pose relative_to='servo5_joint'>0 0 0 0 -0 0</pose>
      <inertial>
        <pose>0.02001 0.00013 -0.001592 0 -0 0</pose>
        <mass>0.09612</mass>
        <inertia>
          <ixx>0.00003584</ixx>
          <ixy>0.00000637</ixy>
          <ixz>0.00000000</ixz>
          <iyy>0.00005438</iyy>
          <iyz>-0.00000000</iyz>
          <izz>0.00004718</izz>
        </inertia>
      </inertial>
      <!-- <collision name='servo5_link_collision'>
        <pose>0 0 0 0 -0 0</pose>
        <geometry>
          <mesh>
            <scale>1 1 1</scale>
            <uri>model://windrobo/meshes/servo5_link.STL</uri>
          </mesh>
        </geometry>
      </collision> -->
      <visual name='servo5_link_visual'>
        <pose>0 0 0 0 -0 0</pose>
        <geometry>
          <mesh>
            <scale>1 1 1</scale>
            <uri>model://windrobo/meshes/servo5_link.dae</uri>
          </mesh>
        </geometry>
      </visual>
    </link>
    <joint name='servo6_joint' type='revolute'>
      <pose relative_to='servo5_link'>0.0618 0 -0.001593 1.5708 -0 1.5708</pose>
      <parent>servo5_link</parent>
      <child>servo6_link</child>
      <axis>
        <xyz>0 0 1</xyz>
        <limit>
          <lower>-2.09</lower>
          <upper>2.09</upper>
          <effort>10</effort>
          <velocity>2</velocity>
        </limit>
        <dynamics>
          <spring_reference>0</spring_reference>
          <!-- <damping>1.0</damping>
          <friction>2.0</friction> -->
          <damping>0.2</damping>
          <friction>0.1</friction>
          <spring_stiffness>0.0</spring_stiffness>
        </dynamics>
      </axis>
    </joint>
    <link name='servo6_link'>
      <pose relative_to='servo6_joint'>0 0 0 0 -0 0</pose>
      <inertial>
        <pose>0.005029 1.3e-05 0.012509 0 -0 0</pose>
        <mass>0.09612</mass>
        <inertia>
          <ixx>0.00003584</ixx>
          <ixy>0.00000637</ixy>
          <ixz>0.00000000</ixz>
          <iyy>0.00005438</iyy>
          <iyz>-0.00000000</iyz>
          <izz>0.00004718</izz>
        </inertia>
      </inertial>
      <!-- <collision name='servo6_link_collision'>
        <pose>0 0 0 0 -0 0</pose>
        <geometry>
          <mesh>
            <scale>1 1 1</scale>
            <uri>model://windrobo/meshes/servo6_link.STL</uri>
          </mesh>
        </geometry>
      </collision> -->
      <visual name='servo6_link_visual'>
        <pose>0 0 0 0 -0 0</pose>
        <geometry>
          <mesh>
            <scale>1 1 1</scale>
            <uri>model://windrobo/meshes/servo6_link.dae</uri>
          </mesh>
        </geometry>
      </visual>
    </link>
    
    <joint name='servo7_joint' type='revolute'>
      <pose relative_to='servo6_link'>0.000726 0 0.039728 -9.3e-05 -1.57079 3.14159</pose>
      <parent>servo6_link</parent>
      <child>servo7_link</child>
      <axis>
        <xyz>0 0 1</xyz>
        <limit>
          <lower>-0.35</lower>
          <upper>1.74</upper>
          <effort>10</effort>
          <velocity>3.14</velocity>
        </limit>
        <dynamics>
          <spring_reference>0</spring_reference>
          <!-- <damping>1.0</damping>
          <friction>2.0</friction> -->
          <damping>0.1</damping>
          <friction>0.01</friction>
          <spring_stiffness>0.0</spring_stiffness> <!--10-->
        </dynamics>
      </axis>
    </joint>

    <link name='servo7_link'>
      <pose relative_to='servo7_joint'>0 0 0 0 -0 0</pose>
      <inertial>
        <pose>0.031979 -0.028224 0.000476 0 -0 0</pose>
        <mass>0.410</mass>
        <inertia>
          <ixx>0.00208911</ixx>
          <ixy>-0.00015149</ixy>
          <ixz>0.00000319</ixz>
          <iyy>0.00228960</iyy>
          <iyz>0.00000190</iyz>
          <izz>0.00064838</izz>
        </inertia>
      </inertial>
      <collision name='servo7_link_collision'>
        <pose>0 0 0 0 -0 0</pose>
        <geometry>
          <mesh>
            <scale>1 1 1</scale>
            <uri>model://windrobo/meshes/servo7_link_collision.STL</uri>
          </mesh>
        </geometry>
      </collision>
      <visual name='servo7_link_visual'>
        <pose>0 0 0 0 -0 0</pose>
        <geometry>
          <mesh>
            <scale>1 1 1</scale>
            <uri>model://windrobo/meshes/servo7_link.dae</uri>
          </mesh>
        </geometry>
        <surface>
          <contact>
            <ode>
              <min_depth>0.0001</min_depth>
              <kp>1e+07</kp>
              <kd>1</kd>
            </ode>
          </contact>
          <friction>
            <ode>
              <mu>0.2</mu> <!-- Friction coefficient -->
              <mu2>0.01</mu2> <!-- Second friction coefficient -->
            </ode>
          </friction>
        </surface>
      </visual>
    </link>

    <!-- <joint name="camera_servo4_joint" type="fixed">
      <pose relative_to='servo4_link'>0.002522 0 0.05 0 0 0</pose>
      <child>camera_servo4_link</child>
      <parent>servo4_link</parent>
      <axis>
        <xyz>0 0 1</xyz>
        <limit>
          <upper>0</upper>
          <lower>0</lower>
        </limit>
      </axis>
    </joint>
    <link name='camera_servo4_link'>
      <pose relative_to='camera_servo4_joint'>0 0 0 0 0 0</pose>
      <inertial>
        <mass>0.015</mass>
        <inertia>
          <ixx>4.15e-6</ixx>
        <ixy>0</ixy>
        <ixz>0</ixz>
        <iyy>2.407e-6</iyy>
        <iyz>0</iyz>
        <izz>2.407e-6</izz>
        </inertia>
      </inertial>
      <collision name='camera_servo7_collision'>
        <geometry>
          <box>
            <size>0.01 0.01 0.01</size>
          </box>
        </geometry>
        <max_contacts>10</max_contacts>
        <surface>
          <contact>
            <ode/>
          </contact>
          <bounce/>
          <friction>
            <ode/>
          </friction>
        </surface>
      </collision>
      <visual name='camera_servo7_visual'>
        <geometry>
          <box>
            <size>0.01 0.01 0.01</size>
          </box>
        </geometry>
      </visual>
      <sensor name='camera' type='camera'>
        <camera name='camera_servo4'>
          <horizontal_fov>1.047</horizontal_fov>
          <image>
            <width>320</width>
            <height>240</height>
          </image>
          <clip>
            <near>0.1</near>
            <far>100</far>
          </clip>
          <lens>
            <type>custom</type>
            <custom_function>
              <c1>1.05</c1>
              <c2>4</c2>
              <f>1</f>
              <fun>tan</fun>
            </custom_function>
            <scale_to_hfov>1</scale_to_hfov>
            <cutoff_angle>3.1415</cutoff_angle>
            <env_texture_size>1080</env_texture_size>
          </lens>
        </camera>
        <always_on>1</always_on>
        <update_rate>30</update_rate>
        <visualize>1</visualize>
        <plugin name='camera_plugin' filename='libgazebo_ros_camera.so'>
            <robotNamespace></robotNamespace>
          <alwaysOn>true</alwaysOn>
          <frame_name>camera_link_optical</frame_name>
          <topicName>/camera/servo4</topicName>
          <updateRate>30.0</updateRate>
          <cameraName>camera_servo4</cameraName>
          <frameName>/robot_camera_link</frameName>
          <CxPrime>320.5</CxPrime>
          <Cx>320.5</Cx>
          <Cy>240.5</Cy>
          <hackBaseline>0</hackBaseline>
          <focalLength>277.191356</focalLength>
          <distortionK1>0.0</distortionK1>
          <distortionK2>0.0</distortionK2>
          <distortionK3>0.0</distortionK3>
          <distortionT1>0.0</distortionT1>
          <distortionT2>0.0</distortionT2>
        </plugin>
      </sensor>
      <self_collide>0</self_collide>
      <kinematic>0</kinematic>
    </link> -->
    <!-- <joint name='camera_servo4_joint' type='fixed'>
      <pose relative_to='servo7_link'>0.002522 0 0.039828 0 0 0</pose>
      <parent>servo7_link</parent>
      <child>camera_servo4_link</child>
    </joint>
    <link name="camera_servo4_link">
      <visual>
        <geometry>
          <box size="0.01 0.03 0.03"/>
        </geometry>
      </visual>  
    </link>
    <joint name="camera_servo7_optical_joint" type='fixed'>
      <pose relative_to='camera_servo4_link'>0 0 0 -1.141 0 -1.141</pose>
      <parent>camera_servo4_link</parent>
      <child>camera_servo7_optical_link</child>
    </joint>
    <link name="camera_servo7_optical_link">
    </link> -->

    <plugin name='rosbag' filename='libgazebo_multirotor_base_plugin.so'>
      <robotNamespace />
      <linkName>base_link</linkName>
      <rotorVelocitySlowdownSim>10</rotorVelocitySlowdownSim>
    </plugin>
    <plugin name='motor_1' filename='libgazebo_motor_model.so'>
      <robotNamespace />
      <jointName>rotor1_joint</jointName>
      <linkName>rotor1_link</linkName>
      <turningDirection>ccw</turningDirection>
      <timeConstantUp>0.0125</timeConstantUp>
      <timeConstantDown>0.025</timeConstantDown>
      <maxRotVelocity>521</maxRotVelocity>
      <motorConstant>0.0002888</motorConstant>
      <momentConstant>0.07077</momentConstant>
      <commandSubTopic>/gazebo/command/motor_speed</commandSubTopic>
      <motorNumber>0</motorNumber>
      <rotorDragCoefficient>0.000919012</rotorDragCoefficient>
      <rollingMomentCoefficient>1e-06</rollingMomentCoefficient>
      <motorSpeedPubTopic>/motor_speed/0</motorSpeedPubTopic>
      <rotorVelocitySlowdownSim>20</rotorVelocitySlowdownSim>
    </plugin>
    <plugin name='motor_2' filename='libgazebo_motor_model.so'>
      <robotNamespace />
      <jointName>rotor2_joint</jointName>
      <linkName>rotor2_link</linkName>
      <turningDirection>cw</turningDirection>
      <timeConstantUp>0.0125</timeConstantUp>
      <timeConstantDown>0.025</timeConstantDown>
      <maxRotVelocity>521</maxRotVelocity>
      <motorConstant>0.0002888</motorConstant>
      <momentConstant>0.07077</momentConstant>
      <commandSubTopic>/gazebo/command/motor_speed</commandSubTopic>
      <motorNumber>1</motorNumber>
      <rotorDragCoefficient>0.000919012</rotorDragCoefficient>
      <rollingMomentCoefficient>1e-06</rollingMomentCoefficient>
      <motorSpeedPubTopic>/motor_speed/1</motorSpeedPubTopic>
      <rotorVelocitySlowdownSim>20</rotorVelocitySlowdownSim>
    </plugin>
    <plugin name='motor_3' filename='libgazebo_motor_model.so'>
      <robotNamespace />
      <jointName>rotor3_joint</jointName>
      <linkName>rotor3_link</linkName>
      <turningDirection>ccw</turningDirection>
      <timeConstantUp>0.0125</timeConstantUp>
      <timeConstantDown>0.025</timeConstantDown>
      <maxRotVelocity>521</maxRotVelocity>
      <motorConstant>0.0002888</motorConstant>
      <momentConstant>0.07077</momentConstant>
      <commandSubTopic>/gazebo/command/motor_speed</commandSubTopic>
      <motorNumber>2</motorNumber>
      <rotorDragCoefficient>0.000919012</rotorDragCoefficient>
      <rollingMomentCoefficient>1e-06</rollingMomentCoefficient>
      <motorSpeedPubTopic>/motor_speed/2</motorSpeedPubTopic>
      <rotorVelocitySlowdownSim>20</rotorVelocitySlowdownSim>
    </plugin>
    <plugin name='motor_4' filename='libgazebo_motor_model.so'>
      <robotNamespace />
      <jointName>rotor4_joint</jointName>
      <linkName>rotor4_link</linkName>
      <turningDirection>cw</turningDirection>
      <timeConstantUp>0.0125</timeConstantUp>
      <timeConstantDown>0.025</timeConstantDown>
      <maxRotVelocity>521</maxRotVelocity>
      <motorConstant>0.0002888</motorConstant>
      <momentConstant>0.07077</momentConstant>
      <commandSubTopic>/gazebo/command/motor_speed</commandSubTopic>
      <motorNumber>3</motorNumber>
      <rotorDragCoefficient>0.000919012</rotorDragCoefficient>
      <rollingMomentCoefficient>1e-06</rollingMomentCoefficient>
      <motorSpeedPubTopic>/motor_speed/3</motorSpeedPubTopic>
      <rotorVelocitySlowdownSim>20</rotorVelocitySlowdownSim>
    </plugin>
    <plugin name='motor_5' filename='libgazebo_motor_model.so'>
      <robotNamespace />
      <jointName>rotor5_joint</jointName>
      <linkName>rotor5_link</linkName>
      <turningDirection>ccw</turningDirection>
      <timeConstantUp>0.0125</timeConstantUp>
      <timeConstantDown>0.025</timeConstantDown>
      <maxRotVelocity>521</maxRotVelocity>
      <motorConstant>0.0002888</motorConstant>
      <momentConstant>0.07077</momentConstant>
      <commandSubTopic>/gazebo/command/motor_speed</commandSubTopic>
      <motorNumber>4</motorNumber>
      <rotorDragCoefficient>0.000919012</rotorDragCoefficient>
      <rollingMomentCoefficient>1e-06</rollingMomentCoefficient>
      <motorSpeedPubTopic>/motor_speed/4</motorSpeedPubTopic>
      <rotorVelocitySlowdownSim>20</rotorVelocitySlowdownSim>
    </plugin>
    <plugin name='motor_6' filename='libgazebo_motor_model.so'>
      <robotNamespace />
      <jointName>rotor6_joint</jointName>
      <linkName>rotor6_link</linkName>
      <turningDirection>cw</turningDirection>
      <timeConstantUp>0.0125</timeConstantUp>
      <timeConstantDown>0.025</timeConstantDown>
      <maxRotVelocity>521</maxRotVelocity>
      <motorConstant>0.0002888</motorConstant>
      <momentConstant>0.07077</momentConstant>
      <commandSubTopic>/gazebo/command/motor_speed</commandSubTopic>
      <motorNumber>5</motorNumber>
      <rotorDragCoefficient>0.000919012</rotorDragCoefficient>
      <rollingMomentCoefficient>1e-06</rollingMomentCoefficient>
      <motorSpeedPubTopic>/motor_speed/5</motorSpeedPubTopic>
      <rotorVelocitySlowdownSim>20</rotorVelocitySlowdownSim>
    </plugin>
    <plugin name='motor_7' filename='libgazebo_motor_model.so'>
      <robotNamespace />
      <jointName>rotor7_joint</jointName>
      <linkName>rotor7_link</linkName>
      <turningDirection>ccw</turningDirection>
      <timeConstantUp>0.0125</timeConstantUp>
      <timeConstantDown>0.025</timeConstantDown>
      <maxRotVelocity>521</maxRotVelocity>
      <motorConstant>0.0002888</motorConstant>
      <momentConstant>0.07077</momentConstant>
      <commandSubTopic>/gazebo/command/motor_speed</commandSubTopic>
      <motorNumber>6</motorNumber>
      <rotorDragCoefficient>0.000919012</rotorDragCoefficient>
      <rollingMomentCoefficient>1e-06</rollingMomentCoefficient>
      <motorSpeedPubTopic>/motor_speed/6</motorSpeedPubTopic>
      <rotorVelocitySlowdownSim>20</rotorVelocitySlowdownSim>
    </plugin>
    <plugin name='motor_8' filename='libgazebo_motor_model.so'>
      <robotNamespace />
      <jointName>rotor8_joint</jointName>
      <linkName>rotor8_link</linkName>
      <turningDirection>cw</turningDirection>
      <timeConstantUp>0.0125</timeConstantUp>
      <timeConstantDown>0.025</timeConstantDown>
      <maxRotVelocity>521</maxRotVelocity>
      <motorConstant>0.0002888</motorConstant>
      <momentConstant>0.07077</momentConstant>
      <commandSubTopic>/gazebo/command/motor_speed</commandSubTopic>
      <motorNumber>7</motorNumber>
      <rotorDragCoefficient>0.000919012</rotorDragCoefficient>
      <rollingMomentCoefficient>1e-06</rollingMomentCoefficient>
      <motorSpeedPubTopic>/motor_speed/7</motorSpeedPubTopic>
      <rotorVelocitySlowdownSim>20</rotorVelocitySlowdownSim>
    </plugin>

    <include>
      <uri>model://gps</uri>
      <!-- <pose>-0.21 0 0.16 0 0 0</pose> -->
      <pose>0 0 0 0 0 0</pose>
      <name>gps0</name>
    </include>
    <joint name='gps0_joint' type='fixed'>
      <child>gps0::link</child>
      <parent>base_link</parent>
    </joint>

    <link name='gps_visual_link'>
      <pose>-0.21 0 0.169 0 0 0</pose>
      <visual name="gps_visual">
        <geometry>
          <mesh>
            <scale>1 1 1</scale>
            <uri>model://windrobo/meshes/gps_link.dae</uri>
          </mesh>
        </geometry>
      </visual>
    </link>
    <joint name='gps_visual_joint' type='fixed'>
      <child>gps_visual_link</child>
      <parent>base_link</parent>
    </joint>

    <plugin name='groundtruth_plugin' filename='libgazebo_groundtruth_plugin.so'>
      <robotNamespace />
    </plugin>
    <plugin name='magnetometer_plugin' filename='libgazebo_magnetometer_plugin.so'>
      <robotNamespace />
      <pubRate>100</pubRate>
      <noiseDensity>0.0004</noiseDensity>
      <randomWalk>6.4e-06</randomWalk>
      <biasCorrelationTime>600</biasCorrelationTime>
      <magTopic>/mag</magTopic>
    </plugin>
    <plugin name='barometer_plugin' filename='libgazebo_barometer_plugin.so'>
      <robotNamespace />
      <pubRate>50</pubRate>
      <baroTopic>/baro</baroTopic>
      <baroDriftPaPerSec>0</baroDriftPaPerSec>
    </plugin>
    <plugin name='mavlink_interface' filename='libgazebo_mavlink_interface.so'>
      <robotNamespace />
      <imuSubTopic>/imu</imuSubTopic>
      <magSubTopic>/mag</magSubTopic>
      <baroSubTopic>/baro</baroSubTopic>
      <mavlink_addr>INADDR_ANY</mavlink_addr>
      <mavlink_tcp_port>4560</mavlink_tcp_port>
      <mavlink_udp_port>14560</mavlink_udp_port>
      <serialEnabled>0</serialEnabled>
      <serialDevice>/dev/ttyACM0</serialDevice>
      <baudRate>921600</baudRate>
      <qgc_addr>INADDR_ANY</qgc_addr>
      <qgc_udp_port>14550</qgc_udp_port>
      <sdk_addr>INADDR_ANY</sdk_addr>
      <sdk_udp_port>14540</sdk_udp_port>
      <hil_mode>0</hil_mode>
      <hil_state_level>0</hil_state_level>
      <send_vision_estimation>0</send_vision_estimation>
      <send_odometry>1</send_odometry>
      <enable_lockstep>1</enable_lockstep>
      <use_tcp>1</use_tcp>
      <motorSpeedCommandPubTopic>/gazebo/command/motor_speed</motorSpeedCommandPubTopic>
      <control_channels>
        <channel name='rotor0'>
          <input_index>0</input_index>
          <input_offset>0</input_offset>
          <input_scaling>521</input_scaling>
          <zero_position_disarmed>0</zero_position_disarmed>
          <zero_position_armed>100</zero_position_armed>
          <joint_control_type>velocity</joint_control_type>
        </channel>
        <channel name='rotor1'>
          <input_index>1</input_index>
          <input_offset>0</input_offset>
          <input_scaling>521</input_scaling>
          <zero_position_disarmed>0</zero_position_disarmed>
          <zero_position_armed>100</zero_position_armed>
          <joint_control_type>velocity</joint_control_type>
        </channel>
        <channel name='rotor2'>
          <input_index>2</input_index>
          <input_offset>0</input_offset>
          <input_scaling>521</input_scaling>
          <zero_position_disarmed>0</zero_position_disarmed>
          <zero_position_armed>100</zero_position_armed>
          <joint_control_type>velocity</joint_control_type>
        </channel>
        <channel name='rotor3'>
          <input_index>3</input_index>
          <input_offset>0</input_offset>
          <input_scaling>521</input_scaling>
          <zero_position_disarmed>0</zero_position_disarmed>
          <zero_position_armed>100</zero_position_armed>
          <joint_control_type>velocity</joint_control_type>
        </channel>
        <channel name='rotor4'>
          <input_index>4</input_index>
          <input_offset>0</input_offset>
          <input_scaling>521</input_scaling>
          <zero_position_disarmed>0</zero_position_disarmed>
          <zero_position_armed>100</zero_position_armed>
          <joint_control_type>velocity</joint_control_type>
        </channel>
        <channel name='rotor5'>
          <input_index>5</input_index>
          <input_offset>0</input_offset>
          <input_scaling>521</input_scaling>
          <zero_position_disarmed>0</zero_position_disarmed>
          <zero_position_armed>100</zero_position_armed>
          <joint_control_type>velocity</joint_control_type>
        </channel>
        <channel name='rotor6'>
          <input_index>6</input_index>
          <input_offset>0</input_offset>
          <input_scaling>521</input_scaling>
          <zero_position_disarmed>0</zero_position_disarmed>
          <zero_position_armed>100</zero_position_armed>
          <joint_control_type>velocity</joint_control_type>
        </channel>
        <channel name='rotor7'>
          <input_index>7</input_index>
          <input_offset>0</input_offset>
          <input_scaling>521</input_scaling>
          <zero_position_disarmed>0</zero_position_disarmed>
          <zero_position_armed>100</zero_position_armed>
          <joint_control_type>velocity</joint_control_type>
        </channel>
      </control_channels>
    </plugin>
    <plugin name='rotors_gazebo_imu_plugin' filename='libgazebo_imu_plugin.so'>
      <robotNamespace></robotNamespace>
      <linkName>/imu_link</linkName>
      <imuTopic>/imu</imuTopic>
      <gyroscopeNoiseDensity>0.0003394</gyroscopeNoiseDensity>
      <gyroscopeRandomWalk>3.8785e-05</gyroscopeRandomWalk>
      <gyroscopeBiasCorrelationTime>1000.0</gyroscopeBiasCorrelationTime>
      <gyroscopeTurnOnBiasSigma>0.0087</gyroscopeTurnOnBiasSigma>
      <accelerometerNoiseDensity>0.004</accelerometerNoiseDensity>
      <accelerometerRandomWalk>0.006</accelerometerRandomWalk>
      <accelerometerBiasCorrelationTime>300.0</accelerometerBiasCorrelationTime>
      <accelerometerTurnOnBiasSigma>0.196</accelerometerTurnOnBiasSigma>
    </plugin>

    <static>0</static>
    <plugin name='gazebo_ros2_control' filename='libgazebo_ros2_control.so'>
      <robot_param>robot_description</robot_param>
      <robot_param_node>robot_state_publisher</robot_param_node>
      <parameters>/src/ros2_environment/windrobo_ws/src/windrobo_controller/config/windrobo_controllers.yaml</parameters>
    </plugin>
    <pose>0 0 0.0 0 -0 0</pose>
  </model>
</sdf>