<sdf version='1.6'>
  <model name='windrobo'>
    <!-- <pose>0 0 0.6 0 0 0</pose>-->
    <link name='base_link'>
      <pose>0 0 0 0 0 0</pose>
      <inertial>
        <pose>-0.011986 0.017766 -0.034181 0 -0 0</pose>
        <mass>25</mass>
        <inertia>
          <ixx>0.0664031</ixx>
          <ixy>0</ixy>
          <ixz>0</ixz>
          <iyy>0.15824</iyy>
          <iyz>0</iyz>
          <izz>0.142881</izz>
        </inertia>
      </inertial>
      <!-- 
      <visual name='base_link_fixed_joint_lump__pcb_link_visual_1'>
        <pose>-0.202281 -0.00167 -0.206791 0 -0 0</pose>
        <geometry>
          <mesh>
            <scale>1 1 1</scale>
            <uri>model://windrobo/meshes/pcb_link.STL</uri>
          </mesh>
        </geometry>
        <material>
          <script>
            <name>Gazebo/DarkGrey</name>
            <uri>file://media/materials/scripts/gazebo.material</uri>
          </script>
        </material>
        <transparency>0</transparency>
        <cast_shadows>1</cast_shadows>
      </visual>-->
      <visual name='base_link_visual'>
        <pose>0 0 0 0 -0 0</pose>
        <geometry>
          <mesh>
            <scale>1 1 1</scale>
            <uri>model://windrobo/meshes/base_link.STL</uri>
          </mesh>
        </geometry>
        <material>
          <script>
            <name>Gazebo/DarkGrey</name>
            <uri>file://media/materials/scripts/gazebo.material</uri>
          </script>
        </material>
        <transparency>0</transparency>
        <cast_shadows>1</cast_shadows>
      </visual>
      <!-- 
      <visual name='base_link_fixed_joint_lump__water_link_visual_2'>
        <pose>-0.32518 0.02883 -0.21379 0 -0 0</pose>
        <geometry>
          <mesh>
            <scale>1 1 1</scale>
            <uri>model://windrobo/meshes/water_link.STL</uri>
          </mesh>
        </geometry>
        <material>
          <script>
            <name>Gazebo/Blue</name>
            <uri>file://media/materials/scripts/gazebo.material</uri>
          </script>
        </material>
        <transparency>0</transparency>
        <cast_shadows>1</cast_shadows>
      </visual>
      -->
      <collision name='base_link_collision'>
        <pose>0 0 -0.18 0 -0 0</pose>
        <geometry>
          <box>
            <size>1 1 0.6</size>
          </box>
        </geometry>
        <surface>
          <contact>
            <ode>
              <min_depth>0.001</min_depth>
              <max_vel>0</max_vel>
            </ode>
          </contact>
          <friction>
            <ode />
          </friction>
        </surface>
      </collision>
      <!-- 
      <collision name='base_link_fixed_joint_lump__pcb_link_collision_1'>
        <pose>-0.202281 -0.00167 -0.206791 0 -0 0</pose>
        <geometry>
          <box>
            <size>0.1 0.1 0.14</size>
          </box>
        </geometry>
        <surface>
          <contact>
            <ode>
              <min_depth>0.001</min_depth>
              <max_vel>0</max_vel>
            </ode>
          </contact>
          <friction>
            <ode />
          </friction>
        </surface>
      </collision>
      <collision name='base_link_fixed_joint_lump__water_link_collision_2'>
        <pose>-0.32518 0.02883 -0.21379 0 -0 0</pose>
        <geometry>
          <box>
            <size>0.1 0.1 0.2</size>
          </box>
        </geometry>
        <surface>
          <contact>
            <ode>
              <min_depth>0.001</min_depth>
              <max_vel>0</max_vel>
            </ode>
          </contact>
          <friction>
            <ode />
          </friction>
        </surface>
      </collision>-->
      <gravity>1</gravity>
      <velocity_decay />
    </link>

    <link name='/imu_link'>
      <pose>0 0 0 0 0 0</pose>
      <inertial>
        <pose>0 0 0.02 0 0 0</pose>
        <mass>0.015</mass>
        <inertia>
          <ixx>1e-05</ixx>
          <ixy>0</ixy>
          <ixz>0</ixz>
          <iyy>1e-05</iyy>
          <iyz>0</iyz>
          <izz>1e-05</izz>
        </inertia>
      </inertial>
    </link>

    <joint name='/imu_joint' type='revolute'>
      <child>/imu_link</child>
      <parent>base_link</parent>
      <axis>
        <xyz>1 0 0</xyz>
        <limit>
          <lower>0</lower>
          <upper>0</upper>
          <effort>0</effort>
          <velocity>0</velocity>
        </limit>
        <dynamics>
          <spring_reference>0</spring_reference>
          <spring_stiffness>0</spring_stiffness>
        </dynamics>
        <use_parent_model_frame>1</use_parent_model_frame>
      </axis>
    </joint>

    <link name='rotor1_link'>
      <pose>0.375836 -0.390942 0.066381 0 -0 0</pose>
      <inertial>
        <pose>1e-06 -0 -0.00116 0 -0 0</pose>
        <mass>0.012</mass>
        <inertia>
          <ixx>7.60115e-05</ixx>
          <ixy>0</ixy>
          <ixz>0</ixz>
          <iyy>0.00199518</iyy>
          <iyz>0</iyz>
          <izz>0.00205661</izz>
        </inertia>
      </inertial>
      <collision name='rotor1_link_collision'>
        <pose>0 0 0 0 -0 0</pose>
        <geometry>
          <mesh>
            <uri>model://windrobo/meshes/rotor1_link.STL</uri>
            <scale>1 1 1</scale>
          </mesh>
        </geometry>
        <surface>
          <contact>
            <ode>
            </ode>
          </contact>
          <friction>
            <ode />
          </friction>
        </surface>
      </collision>
      <visual name='rotor1_link_visual'>
        <pose>0 0 0 0 -0 0</pose>
        <geometry>
          <mesh>
            <scale>1 1 1</scale>
            <uri>model://windrobo/meshes/rotor1_link.STL</uri>
          </mesh>
        </geometry>
        <material>
          <script>
            <name>Gazebo/Blue</name>
            <uri>file://media/materials/scripts/gazebo.material</uri>
          </script>
        </material>
        <transparency>0</transparency>
        <cast_shadows>1</cast_shadows>
      </visual>
      <gravity>1</gravity>
      <velocity_decay />
    </link>
    <joint name='rotor1_joint' type='revolute'>
      <parent>base_link</parent>
      <child>rotor1_link</child>
      <pose>0 0 0 0 -0 0</pose>
      <axis>
        <xyz>0 0 1</xyz>
        <limit>
          <lower>-1e+16</lower>
          <upper>1e+16</upper>
        </limit>
        <dynamics>
          <spring_reference>0</spring_reference>
          <spring_stiffness>0</spring_stiffness>
        </dynamics>
        <use_parent_model_frame>1</use_parent_model_frame>
      </axis>
    </joint>
    <link name='rotor2_link'>
      <pose>0.389645 0.388556 0.066381 0 -0 0</pose>
      <inertial>
        <pose>-1e-06 0 -0.00116 0 -0 0</pose>
        <mass>0.012</mass>
        <inertia>
          <ixx>7.60115e-05</ixx>
          <ixy>0</ixy>
          <ixz>0</ixz>
          <iyy>0.00199518</iyy>
          <iyz>0</iyz>
          <izz>0.00205661</izz>
        </inertia>
      </inertial>
      <collision name='rotor2_link_collision'>
        <pose>0 0 0 0 -0 0</pose>
        <geometry>
          <mesh>
            <uri>model://windrobo/meshes/rotor2_link.STL</uri>
            <scale>1 1 1</scale>
          </mesh>
        </geometry>
        <surface>
          <contact>
            <ode>
            </ode>
          </contact>
          <friction>
            <ode />
          </friction>
        </surface>
      </collision>
      <visual name='rotor2_link_visual'>
        <pose>0 0 0 0 -0 0</pose>
        <geometry>
          <mesh>
            <scale>1 1 1</scale>
            <uri>model://windrobo/meshes/rotor2_link.STL</uri>
          </mesh>
        </geometry>
        <material>
          <script>
            <name>Gazebo/Blue</name>
            <uri>file://media/materials/scripts/gazebo.material</uri>
          </script>
        </material>
        <transparency>0</transparency>
        <cast_shadows>1</cast_shadows>
      </visual>
      <gravity>1</gravity>
      <velocity_decay />
    </link>
    <joint name='rotor2_joint' type='revolute'>
      <parent>base_link</parent>
      <child>rotor2_link</child>
      <pose>0 0 0 0 -0 0</pose>
      <axis>
        <xyz>0 0 1</xyz>
        <limit>
          <lower>-1e+16</lower>
          <upper>1e+16</upper>
        </limit>
        <dynamics>
          <spring_reference>0</spring_reference>
          <spring_stiffness>0</spring_stiffness>
        </dynamics>
        <use_parent_model_frame>1</use_parent_model_frame>
      </axis>
    </joint>
    <link name='rotor3_link'>
      <pose>-0.392192 0.387361 0.066381 0 -0 0</pose>
      <inertial>
        <pose>0 -0 -0.00116 0 -0 0</pose>
        <mass>0.012</mass>
        <inertia>
          <ixx>7.60115e-05</ixx>
          <ixy>0</ixy>
          <ixz>0</ixz>
          <iyy>0.00199518</iyy>
          <iyz>0</iyz>
          <izz>0.00205661</izz>
        </inertia>
      </inertial>
      <collision name='rotor3_link_collision'>
        <pose>0 0 0 0 -0 0</pose>
        <geometry>
          <mesh>
            <uri>model://windrobo/meshes/rotor3_link.STL</uri>
            <scale>1 1 1</scale>
          </mesh>
        </geometry>
        <surface>
          <contact>
            <ode>
            </ode>
          </contact>
          <friction>
            <ode />
          </friction>
        </surface>
      </collision>
      <visual name='rotor3_link_visual'>
        <pose>0 0 0 0 -0 0</pose>
        <geometry>
          <mesh>
            <scale>1 1 1</scale>
            <uri>model://windrobo/meshes/rotor3_link.STL</uri>
          </mesh>
        </geometry>
        <material>
          <script>
            <name>Gazebo/Blue</name>
            <uri>file://media/materials/scripts/gazebo.material</uri>
          </script>
        </material>
        <transparency>0</transparency>
        <cast_shadows>1</cast_shadows>
      </visual>
      <gravity>1</gravity>
      <velocity_decay />
    </link>
    <joint name='rotor3_joint' type='revolute'>
      <parent>base_link</parent>
      <child>rotor3_link</child>
      <pose>0 0 0 0 -0 0</pose>
      <axis>
        <xyz>0 0 1</xyz>
        <limit>
          <lower>-1e+16</lower>
          <upper>1e+16</upper>
        </limit>
        <dynamics>
          <spring_reference>0</spring_reference>
          <spring_stiffness>0</spring_stiffness>
        </dynamics>
        <use_parent_model_frame>1</use_parent_model_frame>
      </axis>
    </joint>
    <link name='rotor4_link'>
      <pose>-0.391001 -0.39209 0.066381 0 -0 0</pose>
      <inertial>
        <pose>0 -0 -0.00116 0 -0 0</pose>
        <mass>0.012</mass>
        <inertia>
          <ixx>7.60115e-05</ixx>
          <ixy>0</ixy>
          <ixz>0</ixz>
          <iyy>0.00199518</iyy>
          <iyz>0</iyz>
          <izz>0.00205661</izz>
        </inertia>
      </inertial>
      <collision name='rotor4_link_collision'>
        <pose>0 0 0 0 -0 0</pose>
        <geometry>
          <mesh>
            <uri>model://windrobo/meshes/rotor4_link.STL</uri>
            <scale>1 1 1</scale>
          </mesh>
        </geometry>
        <surface>
          <contact>
            <ode>
            </ode>
          </contact>
          <friction>
            <ode />
          </friction>
        </surface>
      </collision>
      <visual name='rotor4_link_visual'>
        <pose>0 0 0 0 -0 0</pose>
        <geometry>
          <mesh>
            <scale>1 1 1</scale>
            <uri>model://windrobo/meshes/rotor4_link.STL</uri>
          </mesh>
        </geometry>
        <material>
          <script>
            <name>Gazebo/Blue</name>
            <uri>file://media/materials/scripts/gazebo.material</uri>
          </script>
        </material>
        <transparency>0</transparency>
        <cast_shadows>1</cast_shadows>
      </visual>
      <gravity>1</gravity>
      <velocity_decay />
    </link>
    <joint name='rotor4_joint' type='revolute'>
      <parent>base_link</parent>
      <child>rotor4_link</child>
      <pose>0 0 0 0 -0 0</pose>
      <axis>
        <xyz>0 0 1</xyz>
        <limit>
          <lower>-1e+16</lower>
          <upper>1e+16</upper>
        </limit>
        <dynamics>
          <spring_reference>0</spring_reference>
          <spring_stiffness>0</spring_stiffness>
        </dynamics>
        <use_parent_model_frame>1</use_parent_model_frame>
      </axis>
    </joint>
    <link name='rotor5_link'>
      <pose>0.389645 0.388556 -0.064619 0 -0 0</pose>
      <inertial>
        <pose>0 0 0.00494 0 -0 0</pose>
        <mass>0.012</mass>
        <inertia>
          <ixx>7.60115e-05</ixx>
          <ixy>0</ixy>
          <ixz>0</ixz>
          <iyy>0.00199518</iyy>
          <iyz>0</iyz>
          <izz>0.00205661</izz>
        </inertia>
      </inertial>
      <collision name='rotor5_link_collision'>
        <pose>0 0 0 0 -0 0</pose>
        <geometry>
          <mesh>
            <uri>model://windrobo/meshes/rotor5_link.STL</uri>
            <scale>1 1 1</scale>
          </mesh>
        </geometry>
        <surface>
          <contact>
            <ode>
            </ode>
          </contact>
          <friction>
            <ode />
          </friction>
        </surface>
      </collision>
      <visual name='rotor5_link_visual'>
        <pose>0 0 0 0 -0 0</pose>
        <geometry>
          <mesh>
            <scale>1 1 1</scale>
            <uri>model://windrobo/meshes/rotor5_link.STL</uri>
          </mesh>
        </geometry>
        <material>
          <script>
            <name>Gazebo/Blue</name>
            <uri>file://media/materials/scripts/gazebo.material</uri>
          </script>
        </material>
        <transparency>0</transparency>
        <cast_shadows>1</cast_shadows>
      </visual>
      <gravity>1</gravity>
      <velocity_decay />
    </link>
    <joint name='rotor5_joint' type='revolute'>
      <parent>base_link</parent>
      <child>rotor5_link</child>
      <pose>0 0 0 0 -0 0</pose>
      <axis>
        <xyz>0 0 1</xyz>
        <limit>
          <lower>-1e+16</lower>
          <upper>1e+16</upper>
        </limit>
        <dynamics>
          <spring_reference>0</spring_reference>
          <spring_stiffness>0</spring_stiffness>
        </dynamics>
        <use_parent_model_frame>1</use_parent_model_frame>
      </axis>
    </joint>
    <link name='rotor6_link'>
      <pose>0.390836 -0.390896 -0.064619 0 -0 0</pose>
      <inertial>
        <pose>-1e-06 0 0.00494 0 -0 0</pose>
        <mass>0.012</mass>
        <inertia>
          <ixx>7.60115e-05</ixx>
          <ixy>0</ixy>
          <ixz>0</ixz>
          <iyy>0.00199518</iyy>
          <iyz>0</iyz>
          <izz>0.00205661</izz>
        </inertia>
      </inertial>
      <collision name='rotor6_link_collision'>
        <pose>0 0 0 0 -0 0</pose>
        <geometry>
          <mesh>
            <uri>model://windrobo/meshes/rotor6_link.STL</uri>
            <scale>1 1 1</scale>
          </mesh>
        </geometry>
        <surface>
          <contact>
            <ode>
            </ode>
          </contact>
          <friction>
            <ode />
          </friction>
        </surface>
      </collision>
      <visual name='rotor6_link_visual'>
        <pose>0 0 0 0 -0 0</pose>
        <geometry>
          <mesh>
            <scale>1 1 1</scale>
            <uri>model://windrobo/meshes/rotor6_link.STL</uri>
          </mesh>
        </geometry>
        <material>
          <script>
            <name>Gazebo/Blue</name>
            <uri>file://media/materials/scripts/gazebo.material</uri>
          </script>
        </material>
        <transparency>0</transparency>
        <cast_shadows>1</cast_shadows>
      </visual>
      <gravity>1</gravity>
      <velocity_decay />
    </link>
    <joint name='rotor6_joint' type='revolute'>
      <parent>base_link</parent>
      <child>rotor6_link</child>
      <pose>0 0 0 0 -0 0</pose>
      <axis>
        <xyz>0 0 1</xyz>
        <limit>
          <lower>-1e+16</lower>
          <upper>1e+16</upper>
        </limit>
        <dynamics>
          <spring_reference>0</spring_reference>
          <spring_stiffness>0</spring_stiffness>
        </dynamics>
        <use_parent_model_frame>1</use_parent_model_frame>
      </axis>
    </joint>
    <link name='rotor7_link'>
      <pose>-0.391001 -0.39209 -0.064619 0 -0 0</pose>
      <inertial>
        <pose>-1e-06 1e-06 0.00494 0 -0 0</pose>
        <mass>0.012</mass>
        <inertia>
          <ixx>7.60115e-05</ixx>
          <ixy>0</ixy>
          <ixz>0</ixz>
          <iyy>0.00199518</iyy>
          <iyz>0</iyz>
          <izz>0.00205661</izz>
        </inertia>
      </inertial>
      <collision name='rotor7_link_collision'>
        <pose>0 0 0 0 -0 0</pose>
        <geometry>
          <mesh>
            <uri>model://windrobo/meshes/rotor7_link.STL</uri>
            <scale>1 1 1</scale>
          </mesh>
        </geometry>
        <surface>
          <contact>
            <ode>
            </ode>
          </contact>
          <friction>
            <ode />
          </friction>
        </surface>
      </collision>
      <visual name='rotor7_link_visual'>
        <pose>0 0 0 0 -0 0</pose>
        <geometry>
          <mesh>
            <scale>1 1 1</scale>
            <uri>model://windrobo/meshes/rotor7_link.STL</uri>
          </mesh>
        </geometry>
        <material>
          <script>
            <name>Gazebo/Blue</name>
            <uri>file://media/materials/scripts/gazebo.material</uri>
          </script>
        </material>
        <transparency>0</transparency>
        <cast_shadows>1</cast_shadows>
      </visual>
      <gravity>1</gravity>
      <velocity_decay />
    </link>
    <joint name='rotor7_joint' type='revolute'>
      <parent>base_link</parent>
      <child>rotor7_link</child>
      <pose>0 0 0 0 -0 0</pose>
      <axis>
        <xyz>0 0 1</xyz>
        <limit>
          <lower>-1e+16</lower>
          <upper>1e+16</upper>
        </limit>
        <dynamics>
          <spring_reference>0</spring_reference>
          <spring_stiffness>0</spring_stiffness>
        </dynamics>
        <use_parent_model_frame>1</use_parent_model_frame>
      </axis>
    </joint>
    <link name='rotor8_link'>
      <pose>-0.392192 0.387361 -0.064619 0 -0 0</pose>
      <inertial>
        <pose>0 -0 0.00494 0 -0 0</pose>
        <mass>0.012</mass>
        <inertia>
          <ixx>7.60115e-05</ixx>
          <ixy>0</ixy>
          <ixz>0</ixz>
          <iyy>0.00199518</iyy>
          <iyz>0</iyz>
          <izz>0.00205661</izz>
        </inertia>
      </inertial>
      <collision name='rotor8_link_collision'>
        <pose>0 0 0 0 -0 0</pose>
        <geometry>
          <mesh>
            <uri>model://windrobo/meshes/rotor8_link.STL</uri>
            <scale>1 1 1</scale>
          </mesh>
        </geometry>
        <surface>
          <contact>
            <ode>
            </ode>
          </contact>
          <friction>
            <ode />
          </friction>
        </surface>
      </collision>
      <visual name='rotor8_link_visual'>
        <pose>0 0 0 0 -0 0</pose>
        <geometry>
          <mesh>
            <scale>1 1 1</scale>
            <uri>model://windrobo/meshes/rotor8_link.STL</uri>
          </mesh>
        </geometry>
        <material>
          <script>
            <name>Gazebo/Blue</name>
            <uri>file://media/materials/scripts/gazebo.material</uri>
          </script>
        </material>
        <transparency>0</transparency>
        <cast_shadows>1</cast_shadows>
      </visual>
      <gravity>1</gravity>
      <velocity_decay />
    </link>
    <joint name='rotor8_joint' type='revolute'>
      <parent>base_link</parent>
      <child>rotor8_link</child>
      <pose>0 0 0 0 -0 0</pose>
      <axis>
        <xyz>0 0 1</xyz>
        <limit>
          <lower>-1e+16</lower>
          <upper>1e+16</upper>
        </limit>
        <dynamics>
          <spring_reference>0</spring_reference>
          <spring_stiffness>0</spring_stiffness>
        </dynamics>
        <use_parent_model_frame>1</use_parent_model_frame>
      </axis>
    </joint>
    <!-- 
    <link name='servo1_link'>
      <pose>-8.2e-05 -0.001169 -0.145886 0 -0 0</pose>
      <inertial>
        <pose>0.031107 -6.2e-05 -0.000315 0 -0 0</pose>
        <mass>0.796983</mass>
        <inertia>
          <ixx>0.00105499</ixx>
          <ixy>0</ixy>
          <ixz>0</ixz>
          <iyy>0.00058581</iyy>
          <iyz>0</iyz>
          <izz>0.00112052</izz>
        </inertia>
      </inertial>
      <self_collide>0</self_collide>
      <gravity>1</gravity>
      <visual name='servo1_link_visual'>
        <pose>0 0 0 0 -0 0</pose>
        <geometry>
          <mesh>
            <scale>1 1 1</scale>
            <uri>model://windrobo/meshes/servo1_link.STL</uri>
          </mesh>
        </geometry>
        <material>
          <script>
            <name>Gazebo/DarkGrey</name>
            <uri>file://media/materials/scripts/gazebo.material</uri>
          </script>
        </material>
        <transparency>0</transparency>
        <cast_shadows>1</cast_shadows>
      </visual>
      <collision name='servo1_link_collision'>
        <pose>0 0 0 0 -0 0</pose>
        <geometry>
          <box>
            <size>0.2 0.2 0.1</size>
          </box>
        </geometry>
        <surface>
          <contact>
            <ode>
              <min_depth>0.001</min_depth>
              <max_vel>0</max_vel>
            </ode>
          </contact>
          <friction>
            <ode />
          </friction>
        </surface>
      </collision>
    </link>
    <link name='servo2_link'>
      <pose>0.127418 -0.001343 -0.145461 0 -0 0</pose>
      <inertial>
        <pose>0.195917 -0.004553 -0.005988 0 -0 0</pose>
        <mass>0.900577</mass>
        <inertia>
          <ixx>0.00047839</ixx>
          <ixy>4e-08</ixy>
          <ixz>5.75e-06</ixz>
          <iyy>0.00681705</iyy>
          <iyz>9.23e-06</iyz>
          <izz>0.00667121</izz>
        </inertia>
      </inertial>
      <self_collide>0</self_collide>
      <gravity>1</gravity>
      <visual name='servo2_link_visual'>
        <pose>0 0 0 0 -0 0</pose>
        <geometry>
          <mesh>
            <scale>1 1 1</scale>
            <uri>model://windrobo/meshes/servo2_link.STL</uri>
          </mesh>
        </geometry>
        <material>
          <script>
            <name>Gazebo/DarkGrey</name>
            <uri>file://media/materials/scripts/gazebo.material</uri>
          </script>
        </material>
        <transparency>0</transparency>
        <cast_shadows>1</cast_shadows>
      </visual>
      <collision name='servo2_link_collision'>
        <pose>0.15 0 0 0 -0 0</pose>
        <geometry>
          <box>
            <size>0.5 0.1 0.1</size>
          </box>
        </geometry>
        <surface>
          <contact>
            <ode>
              <min_depth>0.001</min_depth>
              <max_vel>0</max_vel>
            </ode>
          </contact>
          <friction>
            <ode />
          </friction>
        </surface>
      </collision>
    </link>
    <link name='servo3_link'>
      <pose>0.498418 -0.001343 -0.145761 0 -0 0</pose>
      <inertial>
        <pose>0.141621 -0.000233 -0.000786 0 -0 0</pose>
        <mass>0.136452</mass>
        <inertia>
          <ixx>3.458e-05</ixx>
          <ixy>-0</ixy>
          <ixz>0</ixz>
          <iyy>0.00030391</iyy>
          <iyz>0</iyz>
          <izz>0.00028426</izz>
        </inertia>
      </inertial>
      <self_collide>0</self_collide>
      <gravity>1</gravity>
      <visual name='servo3_link_visual'>
        <pose>0 0 0 0 -0 0</pose>
        <geometry>
          <mesh>
            <scale>1 1 1</scale>
            <uri>model://windrobo/meshes/servo3_link.STL</uri>
          </mesh>
        </geometry>
        <material>
          <script>
            <name>Gazebo/DarkGrey</name>
            <uri>file://media/materials/scripts/gazebo.material</uri>
          </script>
        </material>
        <transparency>0</transparency>
        <cast_shadows>1</cast_shadows>
      </visual>
      <collision name='servo3_link_collision'>
        <pose>0.2 0 0 0 -0 0</pose>
        <geometry>
          <box>
            <size>0.25 0.1 0.1</size>
          </box>
        </geometry>
        <surface>
          <contact>
            <ode>
              <min_depth>0.001</min_depth>
              <max_vel>0</max_vel>
            </ode>
          </contact>
          <friction>
            <ode />
          </friction>
        </surface>
      </collision>
    </link>
    <link name='servo4_link'>
      <pose>0.824246 -0.001343 -0.145736 0 -0 0</pose>
      <inertial>
        <pose>0.079649 0.002221 -0.000146 0 -0 0</pose>
        <mass>0.134953</mass>
        <inertia>
          <ixx>4.02905e-05</ixx>
          <ixy>7.21112e-07</ixy>
          <ixz>-2.38704e-07</ixz>
          <iyy>6.17509e-05</iyy>
          <iyz>1.13338e-10</iyz>
          <izz>6.30335e-05</izz>
        </inertia>
      </inertial>
      <self_collide>0</self_collide>
      <visual name='servo4_link_visual'>
        <pose>0 0 0 0 -0 0</pose>
        <geometry>
          <mesh>
            <scale>1 1 1</scale>
            <uri>model://windrobo/meshes/servo4_link.STL</uri>
          </mesh>
        </geometry>
        <material>
          <script>
            <name>Gazebo/DarkGrey</name>
            <uri>file://media/materials/scripts/gazebo.material</uri>
          </script>
        </material>
        <transparency>0</transparency>
        <cast_shadows>1</cast_shadows>
      </visual>
      <collision name='servo4_link_collision'>
        <pose>0 0 0 0 -0 0</pose>
        <geometry>
          <mesh>
            <uri>model://windrobo/meshes/servo4_link.STL</uri>
            <scale>1 1 1</scale>
          </mesh>
        </geometry>
        <surface>
          <contact>
            <ode>
              <min_depth>0.001</min_depth>
              <max_vel>0</max_vel>
            </ode>
          </contact>
          <friction>
            <ode />
          </friction>
        </surface>
      </collision>
    </link>
    <link name='servo5_link'>
      <pose>0.934646 -0.001043 -0.145736 1.5708 -0 0</pose>
      <inertial>
        <pose>0.017311 2.1e-05 0 0 -0 0</pose>
        <mass>0.0143386</mass>
        <inertia>
          <ixx>8.24e-06</ixx>
          <ixy>-0</ixy>
          <ixz>-0</ixz>
          <iyy>8.91e-06</iyy>
          <iyz>0</iyz>
          <izz>2.77e-06</izz>
        </inertia>
      </inertial>
      <self_collide>0</self_collide>
      <gravity>1</gravity>
      <visual name='servo5_link_visual'>
        <pose>0 0 0 0 -0 0</pose>
        <geometry>
          <mesh>
            <scale>1 1 1</scale>
            <uri>model://windrobo/meshes/servo5_link.STL</uri>
          </mesh>
        </geometry>
        <material>
          <script>
            <name>Gazebo/DarkGrey</name>
            <uri>file://media/materials/scripts/gazebo.material</uri>
          </script>
        </material>
        <transparency>0</transparency>
        <cast_shadows>1</cast_shadows>
      </visual>
      <collision name='servo5_link_collision'>
        <pose>0 0 0 0 -0 0</pose>
        <geometry>
          <box>
            <size>0.08 0.03 0.1</size>
          </box>
        </geometry>
        <surface>
          <contact>
            <ode>
              <min_depth>0.001</min_depth>
              <max_vel>0</max_vel>
            </ode>
          </contact>
          <friction>
            <ode />
          </friction>
        </surface>
      </collision>
    </link>
    <link name='servo6_link'>
      <pose>0.996746 -0.001043 -0.148408 -0.786597 -1.57079 -2.35499</pose>
      <inertial>
        <pose>-0.005163 9e-06 0.013375 0 -0 0</pose>
        <mass>0.00518033</mass>
        <inertia>
          <ixx>1.9e-07</ixx>
          <ixy>-0</ixy>
          <ixz>0</ixz>
          <iyy>3e-07</iyy>
          <iyz>0</iyz>
          <izz>4.4e-07</izz>
        </inertia>
      </inertial>
      <self_collide>0</self_collide>
      <gravity>1</gravity>
      <visual name='servo6_link_visual'>
        <pose>0 0 0 0 -0 0</pose>
        <geometry>
          <mesh>
            <scale>1 1 1</scale>
            <uri>model://windrobo/meshes/servo6_link.STL</uri>
          </mesh>
        </geometry>
        <material>
          <script>
            <name>Gazebo/DarkGrey</name>
            <uri>file://media/materials/scripts/gazebo.material</uri>
          </script>
        </material>
        <transparency>0</transparency>
        <cast_shadows>1</cast_shadows>
      </visual>
      <collision name='servo6_link_collision'>
        <pose>0 0 0 0 -0 0</pose>
        <geometry>
          <box>
            <size>0.03 0.05 0.05</size>
          </box>
        </geometry>
        <surface>
          <contact>
            <ode>
              <min_depth>0.001</min_depth>
              <max_vel>0</max_vel>
            </ode>
          </contact>
          <friction>
            <ode />
          </friction>
        </surface>
      </collision>
    </link>
    <link name='servo7_link'>
      <pose>1.03657 -0.001043 -0.146808 1.3e-05 3e-06 4e-06</pose>
      <inertial>
        <pose>0.034068 -0.027252 0.003234 0 -0 0</pose>
        <mass>0.482315</mass>
        <inertia>
          <ixx>0.00182623</ixx>
          <ixy>-5.01202e-06</ixy>
          <ixz>7.79296e-07</ixz>
          <iyy>0.00192297</iyy>
          <iyz>-7.00862e-06</iyz>
          <izz>0.000153396</izz>
        </inertia>
      </inertial>
      <self_collide>0</self_collide>
      <visual name='servo7_link_visual'>
        <pose>0 0 0 0 -0 0</pose>
        <geometry>
          <mesh>
            <scale>1 1 1</scale>
            <uri>model://windrobo/meshes/servo7_link.STL</uri>
          </mesh>
        </geometry>
        <material>
          <script>
            <name>Gazebo/DarkGrey</name>
            <uri>file://media/materials/scripts/gazebo.material</uri>
          </script>
        </material>
        <transparency>0</transparency>
        <cast_shadows>1</cast_shadows>
      </visual>
      <collision name='servo7_link_collision'>
        <pose>0 0 0 0 -0 0</pose>
        <geometry>
          <mesh>
            <uri>model://windrobo/meshes/servo7_link.STL</uri>
            <scale>1 1 1</scale>
          </mesh>
        </geometry>
        <surface>
          <contact>
            <ode>
              <min_depth>0.001</min_depth>
              <max_vel>0</max_vel>
            </ode>
          </contact>
          <friction>
            <ode />
          </friction>
        </surface>
      </collision>
    </link>
    -->

    <!--
    <joint name='servo1_joint' type='prismatic'>
      <parent>base_link</parent>
      <child>servo1_link</child>
      <pose>0 0 0 0 -0 0</pose>
      <axis>
        <xyz>0 0 1</xyz>
        <limit>
          <lower>0</lower>
          <upper>0</upper>
          <effort>1000</effort>
          <velocity>0</velocity>
        </limit>
        <dynamics>
          <spring_reference>0</spring_reference>
          <spring_stiffness>0</spring_stiffness>
          <damping>0</damping>
          <friction>0</friction>
        </dynamics>
      </axis>
      <physics>
        <ode>
          <limit>
            <cfm>0</cfm>
            <erp>0.2</erp>
          </limit>
          <suspension>
            <cfm>0</cfm>
            <erp>0.2</erp>
          </suspension>
        </ode>
      </physics>
    </joint>
    <joint name='servo2_joint' type='revolute'>
      <parent>servo1_link</parent>
      <child>servo2_link</child>
      <pose>0 0 -0 0 -0 0</pose>
      <axis>
        <xyz>0 0 1</xyz>
        <limit>
          <lower>0</lower>
          <upper>0</upper>
          <effort>30</effort>
          <velocity>6.28</velocity>
        </limit>
        <dynamics>
          <spring_reference>0</spring_reference>
          <spring_stiffness>0</spring_stiffness>
          <damping>0</damping>
          <friction>0</friction>
        </dynamics>
      </axis>
      <physics>
        <ode>
          <limit>
            <cfm>0</cfm>
            <erp>0.2</erp>
          </limit>
          <suspension>
            <cfm>0</cfm>
            <erp>0.2</erp>
          </suspension>
        </ode>
      </physics>
    </joint>
    <joint name='servo3_joint' type='revolute'>
      <parent>servo2_link</parent>
      <child>servo3_link</child>
      <pose>0 0 0 0 -0 0</pose>
      <axis>
        <xyz>0 0 1</xyz>
        <limit>
          <lower>0</lower>
          <upper>0</upper>
          <effort>16</effort>
          <velocity>6.28</velocity>
        </limit>
        <dynamics>
          <spring_reference>0</spring_reference>
          <spring_stiffness>0</spring_stiffness>
          <damping>0</damping>
          <friction>0</friction>
        </dynamics>
      </axis>
      <physics>
        <ode>
          <limit>
            <cfm>0</cfm>
            <erp>0.2</erp>
          </limit>
          <suspension>
            <cfm>0</cfm>
            <erp>0.2</erp>
          </suspension>
        </ode>
      </physics>
    </joint>
    <joint name='servo4_joint' type='revolute'>
      <parent>servo3_link</parent>
      <child>servo4_link</child>
      <pose>0 0 -0 0 -0 0</pose>
      <axis>
        <xyz>0 0 1</xyz>
        <limit>
          <lower>0</lower>
          <upper>0</upper>
          <effort>15</effort>
          <velocity>6.28</velocity>
        </limit>
        <dynamics>
          <spring_reference>0</spring_reference>
          <spring_stiffness>0</spring_stiffness>
          <damping>0</damping>
          <friction>0</friction>
        </dynamics>
      </axis>
      <physics>
        <ode>
          <limit>
            <cfm>0</cfm>
            <erp>0.2</erp>
          </limit>
          <suspension>
            <cfm>0</cfm>
            <erp>0.2</erp>
          </suspension>
        </ode>
      </physics>
    </joint>
    <joint name='servo5_joint' type='revolute'>
      <parent>servo4_link</parent>
      <child>servo5_link</child>
      <pose>0 -0 0 0 -0 0</pose>
      <axis>
        <xyz>0 0 1</xyz>
        <limit>
          <lower>0</lower>
          <upper>0</upper>
          <effort>11</effort>
          <velocity>3.14</velocity>
        </limit>
        <dynamics>
          <spring_reference>0</spring_reference>
          <spring_stiffness>0</spring_stiffness>
          <damping>0</damping>
          <friction>0</friction>
        </dynamics>
      </axis>
      <physics>
        <ode>
          <limit>
            <cfm>0</cfm>
            <erp>0.2</erp>
          </limit>
          <suspension>
            <cfm>0</cfm>
            <erp>0.2</erp>
          </suspension>
        </ode>
      </physics>
    </joint>
    <joint name='servo6_joint' type='revolute'>
      <parent>servo5_link</parent>
      <child>servo6_link</child>
      <pose>0 -0 0 0 -0 0</pose>
      <axis>
        <xyz>0 0 1</xyz>
        <limit>
          <lower>0</lower>
          <upper>0</upper>
          <effort>4</effort>
          <velocity>3.14</velocity>
        </limit>
        <dynamics>
          <spring_reference>0</spring_reference>
          <spring_stiffness>0</spring_stiffness>
          <damping>0</damping>
          <friction>0</friction>
        </dynamics>
      </axis>
      <physics>
        <ode>
          <limit>
            <cfm>0</cfm>
            <erp>0.2</erp>
          </limit>
          <suspension>
            <cfm>0</cfm>
            <erp>0.2</erp>
          </suspension>
        </ode>
      </physics>
    </joint>
    <joint name='servo7_joint' type='revolute'>
      <parent>servo6_link</parent>
      <child>servo7_link</child>
      <pose>-0 -0 0 0 -0 0</pose>
      <axis>
        <xyz>0 0 1</xyz>
        <limit>
          <lower>0</lower>
          <upper>0</upper>
          <effort>4</effort>
          <velocity>3.14</velocity>
        </limit>
        <dynamics>
          <spring_reference>0</spring_reference>
          <spring_stiffness>0</spring_stiffness>
          <damping>0</damping>
          <friction>0</friction>
        </dynamics>
      </axis>
      <physics>
        <ode>
          <limit>
            <cfm>0</cfm>
            <erp>0.2</erp>
          </limit>
          <suspension>
            <cfm>0</cfm>
            <erp>0.2</erp>
          </suspension>
        </ode>
      </physics>
    </joint>
    -->

    <!-- Sensors links and joint definition-->

    <!--<include>
      <uri>model://magnetometer</uri>
      <pose>0 0.16 0.367 0 0 3.14159</pose>
      <name>mag</name>
    </include>

    <joint name='mag_joint' type='fixed'>
      <child>mag::link</child>
      <parent>base_link</parent>
    </joint>
   -->
    <!-- Plugin Definiton-->
    <plugin name='rosbag' filename='libgazebo_multirotor_base_plugin.so'>
      <robotNamespace />
      <linkName>base_link</linkName>
      <rotorVelocitySlowdownSim>10</rotorVelocitySlowdownSim>
    </plugin>
    <plugin name='motor_1' filename='libgazebo_motor_model.so'>
      <robotNamespace />
      <jointName>rotor1_joint</jointName>
      <linkName>rotor1_link</linkName>
      <turningDirection>ccw</turningDirection>
      <timeConstantUp>0.0125</timeConstantUp>
      <timeConstantDown>0.025</timeConstantDown>
      <maxRotVelocity>521</maxRotVelocity>
      <motorConstant>0.0002888</motorConstant>
      <momentConstant>0.07077</momentConstant>
      <commandSubTopic>/gazebo/command/motor_speed</commandSubTopic>
      <motorNumber>0</motorNumber>
      <rotorDragCoefficient>0.000919012</rotorDragCoefficient>
      <rollingMomentCoefficient>1e-06</rollingMomentCoefficient>
      <motorSpeedPubTopic>/motor_speed/0</motorSpeedPubTopic>
      <rotorVelocitySlowdownSim>10</rotorVelocitySlowdownSim>
    </plugin>
    <plugin name='motor_2' filename='libgazebo_motor_model.so'>
      <robotNamespace />
      <jointName>rotor2_joint</jointName>
      <linkName>rotor2_link</linkName>
      <turningDirection>cw</turningDirection>
      <timeConstantUp>0.0125</timeConstantUp>
      <timeConstantDown>0.025</timeConstantDown>
      <maxRotVelocity>521</maxRotVelocity>
      <motorConstant>0.0002888</motorConstant>
      <momentConstant>0.07077</momentConstant>
      <commandSubTopic>/gazebo/command/motor_speed</commandSubTopic>
      <motorNumber>1</motorNumber>
      <rotorDragCoefficient>0.000919012</rotorDragCoefficient>
      <rollingMomentCoefficient>1e-06</rollingMomentCoefficient>
      <motorSpeedPubTopic>/motor_speed/1</motorSpeedPubTopic>
      <rotorVelocitySlowdownSim>10</rotorVelocitySlowdownSim>
    </plugin>
    <plugin name='motor_3' filename='libgazebo_motor_model.so'>
      <robotNamespace />
      <jointName>rotor3_joint</jointName>
      <linkName>rotor3_link</linkName>
      <turningDirection>ccw</turningDirection>
      <timeConstantUp>0.0125</timeConstantUp>
      <timeConstantDown>0.025</timeConstantDown>
      <maxRotVelocity>521</maxRotVelocity>
      <motorConstant>0.0002888</motorConstant>
      <momentConstant>0.07077</momentConstant>
      <commandSubTopic>/gazebo/command/motor_speed</commandSubTopic>
      <motorNumber>2</motorNumber>
      <rotorDragCoefficient>0.000919012</rotorDragCoefficient>
      <rollingMomentCoefficient>1e-06</rollingMomentCoefficient>
      <motorSpeedPubTopic>/motor_speed/2</motorSpeedPubTopic>
      <rotorVelocitySlowdownSim>10</rotorVelocitySlowdownSim>
    </plugin>
    <plugin name='motor_4' filename='libgazebo_motor_model.so'>
      <robotNamespace />
      <jointName>rotor4_joint</jointName>
      <linkName>rotor4_link</linkName>
      <turningDirection>cw</turningDirection>
      <timeConstantUp>0.0125</timeConstantUp>
      <timeConstantDown>0.025</timeConstantDown>
      <maxRotVelocity>521</maxRotVelocity>
      <motorConstant>0.0002888</motorConstant>
      <momentConstant>0.07077</momentConstant>
      <commandSubTopic>/gazebo/command/motor_speed</commandSubTopic>
      <motorNumber>3</motorNumber>
      <rotorDragCoefficient>0.000919012</rotorDragCoefficient>
      <rollingMomentCoefficient>1e-06</rollingMomentCoefficient>
      <motorSpeedPubTopic>/motor_speed/3</motorSpeedPubTopic>
      <rotorVelocitySlowdownSim>10</rotorVelocitySlowdownSim>
    </plugin>
    <plugin name='motor_5' filename='libgazebo_motor_model.so'>
      <robotNamespace />
      <jointName>rotor5_joint</jointName>
      <linkName>rotor5_link</linkName>
      <turningDirection>ccw</turningDirection>
      <timeConstantUp>0.0125</timeConstantUp>
      <timeConstantDown>0.025</timeConstantDown>
      <maxRotVelocity>521</maxRotVelocity>
      <motorConstant>0.0002888</motorConstant>
      <momentConstant>0.07077</momentConstant>
      <commandSubTopic>/gazebo/command/motor_speed</commandSubTopic>
      <motorNumber>4</motorNumber>
      <rotorDragCoefficient>0.000919012</rotorDragCoefficient>
      <rollingMomentCoefficient>1e-06</rollingMomentCoefficient>
      <motorSpeedPubTopic>/motor_speed/4</motorSpeedPubTopic>
      <rotorVelocitySlowdownSim>10</rotorVelocitySlowdownSim>
    </plugin>
    <plugin name='motor_6' filename='libgazebo_motor_model.so'>
      <robotNamespace />
      <jointName>rotor6_joint</jointName>
      <linkName>rotor6_link</linkName>
      <turningDirection>cw</turningDirection>
      <timeConstantUp>0.0125</timeConstantUp>
      <timeConstantDown>0.025</timeConstantDown>
      <maxRotVelocity>521</maxRotVelocity>
      <motorConstant>0.0002888</motorConstant>
      <momentConstant>0.07077</momentConstant>
      <commandSubTopic>/gazebo/command/motor_speed</commandSubTopic>
      <motorNumber>5</motorNumber>
      <rotorDragCoefficient>0.000919012</rotorDragCoefficient>
      <rollingMomentCoefficient>1e-06</rollingMomentCoefficient>
      <motorSpeedPubTopic>/motor_speed/5</motorSpeedPubTopic>
      <rotorVelocitySlowdownSim>10</rotorVelocitySlowdownSim>
    </plugin>
    <plugin name='motor_7' filename='libgazebo_motor_model.so'>
      <robotNamespace />
      <jointName>rotor7_joint</jointName>
      <linkName>rotor7_link</linkName>
      <turningDirection>ccw</turningDirection>
      <timeConstantUp>0.0125</timeConstantUp>
      <timeConstantDown>0.025</timeConstantDown>
      <maxRotVelocity>521</maxRotVelocity>
      <motorConstant>0.0002888</motorConstant>
      <momentConstant>0.07077</momentConstant>
      <commandSubTopic>/gazebo/command/motor_speed</commandSubTopic>
      <motorNumber>6</motorNumber>
      <rotorDragCoefficient>0.000919012</rotorDragCoefficient>
      <rollingMomentCoefficient>1e-06</rollingMomentCoefficient>
      <motorSpeedPubTopic>/motor_speed/6</motorSpeedPubTopic>
      <rotorVelocitySlowdownSim>10</rotorVelocitySlowdownSim>
    </plugin>
    <plugin name='motor_8' filename='libgazebo_motor_model.so'>
      <robotNamespace />
      <jointName>rotor8_joint</jointName>
      <linkName>rotor8_link</linkName>
      <turningDirection>cw</turningDirection>
      <timeConstantUp>0.0125</timeConstantUp>
      <timeConstantDown>0.025</timeConstantDown>
      <maxRotVelocity>521</maxRotVelocity>
      <motorConstant>0.0002888</motorConstant>
      <momentConstant>0.07077</momentConstant>
      <commandSubTopic>/gazebo/command/motor_speed</commandSubTopic>
      <motorNumber>7</motorNumber>
      <rotorDragCoefficient>0.000919012</rotorDragCoefficient>
      <rollingMomentCoefficient>1e-06</rollingMomentCoefficient>
      <motorSpeedPubTopic>/motor_speed/7</motorSpeedPubTopic>
      <rotorVelocitySlowdownSim>10</rotorVelocitySlowdownSim>
    </plugin>
    <include>
      <uri>model://gps</uri>
      <pose>0 0 0 0 0 0</pose>
      <name>gps0</name>
    </include>
    <joint name='gps0_joint' type='fixed'>
      <child>gps0::link</child>
      <parent>base_link</parent>
    </joint>
    <plugin name='groundtruth_plugin' filename='libgazebo_groundtruth_plugin.so'>
      <robotNamespace />
    </plugin>
    <plugin name='magnetometer_plugin' filename='libgazebo_magnetometer_plugin.so'>
      <robotNamespace />
      <pubRate>100</pubRate>
      <noiseDensity>0.0004</noiseDensity>
      <randomWalk>6.4e-06</randomWalk>
      <biasCorrelationTime>600</biasCorrelationTime>
      <magTopic>/mag</magTopic>
    </plugin>
    <plugin name='barometer_plugin' filename='libgazebo_barometer_plugin.so'>
      <robotNamespace />
      <pubRate>50</pubRate>
      <baroTopic>/baro</baroTopic>
      <baroDriftPaPerSec>0</baroDriftPaPerSec>
    </plugin>
    <plugin name='mavlink_interface' filename='libgazebo_mavlink_interface.so'>
      <robotNamespace />
      <imuSubTopic>/imu</imuSubTopic>
      <magSubTopic>/mag</magSubTopic>
      <baroSubTopic>/baro</baroSubTopic>
      <mavlink_addr>INADDR_ANY</mavlink_addr>
      <mavlink_tcp_port>4560</mavlink_tcp_port>
      <mavlink_udp_port>14560</mavlink_udp_port>
      <serialEnabled>0</serialEnabled>
      <serialDevice>/dev/ttyACM0</serialDevice>
      <baudRate>921600</baudRate>
      <qgc_addr>INADDR_ANY</qgc_addr>
      <qgc_udp_port>14550</qgc_udp_port>
      <sdk_addr>INADDR_ANY</sdk_addr>
      <sdk_udp_port>14540</sdk_udp_port>
      <hil_mode>0</hil_mode>
      <hil_state_level>0</hil_state_level>
      <send_vision_estimation>0</send_vision_estimation>
      <send_odometry>1</send_odometry>
      <enable_lockstep>1</enable_lockstep>
      <use_tcp>1</use_tcp>
      <motorSpeedCommandPubTopic>/gazebo/command/motor_speed</motorSpeedCommandPubTopic>
      <control_channels>
        <channel name='rotor0'>
          <input_index>0</input_index>
          <input_offset>0</input_offset>
          <input_scaling>521</input_scaling>
          <zero_position_disarmed>0</zero_position_disarmed>
          <zero_position_armed>0</zero_position_armed>
          <joint_control_type>velocity</joint_control_type>
        </channel>
        <channel name='rotor1'>
          <input_index>1</input_index>
          <input_offset>0</input_offset>
          <input_scaling>521</input_scaling>
          <zero_position_disarmed>0</zero_position_disarmed>
          <zero_position_armed>0</zero_position_armed>
          <joint_control_type>velocity</joint_control_type>
        </channel>
        <channel name='rotor2'>
          <input_index>2</input_index>
          <input_offset>0</input_offset>
          <input_scaling>521</input_scaling>
          <zero_position_disarmed>0</zero_position_disarmed>
          <zero_position_armed>0</zero_position_armed>
          <joint_control_type>velocity</joint_control_type>
        </channel>
        <channel name='rotor3'>
          <input_index>3</input_index>
          <input_offset>0</input_offset>
          <input_scaling>521</input_scaling>
          <zero_position_disarmed>0</zero_position_disarmed>
          <zero_position_armed>0</zero_position_armed>
          <joint_control_type>velocity</joint_control_type>
        </channel>
        <channel name='rotor4'>
          <input_index>4</input_index>
          <input_offset>0</input_offset>
          <input_scaling>521</input_scaling>
          <zero_position_disarmed>0</zero_position_disarmed>
          <zero_position_armed>0</zero_position_armed>
          <joint_control_type>velocity</joint_control_type>
        </channel>
        <channel name='rotor5'>
          <input_index>5</input_index>
          <input_offset>0</input_offset>
          <input_scaling>521</input_scaling>
          <zero_position_disarmed>0</zero_position_disarmed>
          <zero_position_armed>0</zero_position_armed>
          <joint_control_type>velocity</joint_control_type>
        </channel>
        <channel name='rotor6'>
          <input_index>6</input_index>
          <input_offset>0</input_offset>
          <input_scaling>521</input_scaling>
          <zero_position_disarmed>0</zero_position_disarmed>
          <zero_position_armed>0</zero_position_armed>
          <joint_control_type>velocity</joint_control_type>
        </channel>
        <channel name='rotor7'>
          <input_index>7</input_index>
          <input_offset>0</input_offset>
          <input_scaling>521</input_scaling>
          <zero_position_disarmed>0</zero_position_disarmed>
          <zero_position_armed>0</zero_position_armed>
          <joint_control_type>velocity</joint_control_type>
        </channel>
      </control_channels>
    </plugin>
    <plugin name='rotors_gazebo_imu_plugin' filename='libgazebo_imu_plugin.so'>
      <robotNamespace></robotNamespace>
      <linkName>/imu_link</linkName>
      <imuTopic>/imu</imuTopic>
      <gyroscopeNoiseDensity>0.0003394</gyroscopeNoiseDensity>
      <gyroscopeRandomWalk>3.8785e-05</gyroscopeRandomWalk>
      <gyroscopeBiasCorrelationTime>1000.0</gyroscopeBiasCorrelationTime>
      <gyroscopeTurnOnBiasSigma>0.0087</gyroscopeTurnOnBiasSigma>
      <accelerometerNoiseDensity>0.004</accelerometerNoiseDensity>
      <accelerometerRandomWalk>0.006</accelerometerRandomWalk>
      <accelerometerBiasCorrelationTime>300.0</accelerometerBiasCorrelationTime>
      <accelerometerTurnOnBiasSigma>0.196</accelerometerTurnOnBiasSigma>
    </plugin>
    <static>0</static>
  </model>
</sdf>