<sdf version='1.7'>
  <model name='s500'>
    <link name='base_link'>
      <inertial>
        <pose>-0.003953 -0.000376 -0.01378 0 -0 0</pose>
        <mass>1.623</mass>
        <inertia>
          <ixx>0.035125</ixx>
          <ixy>0</ixy>
          <ixz>0</ixz>
          <iyy>0.035125</iyy>
          <iyz>0</iyz>
          <izz>0.060225</izz>
        </inertia>
      </inertial>
      <collision name='base_link_collision'>
        <pose>0 0 0 0 -0 0</pose>
        <geometry>
          <box>
            <size>0.32 0.6 0.35</size>
          </box>
        </geometry>
      </collision>
      <visual name='base_link_visual'>
        <pose>0 0 0 0 -0 0</pose>
        <geometry>
          <mesh>
            <scale>1 1 1</scale>
            <uri>model://s500/meshes/base_link.STL</uri>
          </mesh>
        </geometry>
      </visual>
    </link>
    <!-- battery link and joint-->
    <joint name="battery_joint" type="fixed">
      <child>battery_link</child>
      <parent>base_link</parent>
    </joint>
    <link name="battery_link">
      <pose>-0.07 -0.001506 -0.0195 0 -0 0</pose>
      <inertial>
        <pose>0.14 0 -0.015 0 -0 0</pose>
        <mass>0.394</mass>
        <inertia>
          <ixx>0.0003199</ixx>
          <ixy>0</ixy>
          <ixz>0</ixz>
          <iyy>0.00365</iyy>
          <iyz>0</iyz>
          <izz>0.00365</izz>
        </inertia>
      </inertial>
      <visual name="battery_visual">
        <geometry>
          <mesh>
            <scale>1 1 1</scale>
            <uri>model://s500/meshes/battery_link.STL</uri>
          </mesh>
        </geometry>
      </visual>
      <collision name='battery_collision'>
        <geometry>
          <mesh>
            <scale>1 1 1</scale>
            <uri>model://s500/meshes/battery_link.STL</uri>
          </mesh>
        </geometry>
      </collision>
    </link>
    <!-- jetson link and join-->
    <joint name="jetson_joint" type="fixed">
      <child>jetson_link</child>
      <parent>base_link</parent>
    </joint>
    <link name="jetson_link">
      <pose>-0.085723 -0.001506 -0.0195 0 -0 0</pose>
      <inertial>
        <pose>0 0 -0.0195 0 0 0</pose>
        <mass>0.250</mass>
        <inertia>
          <ixx>0.000219</ixx>
          <ixy>0</ixy>
          <ixz>0</ixz>
          <iyy>0.00269</iyy>
          <iyz>0</iyz>
          <izz>0.00269</izz>
        </inertia>
      </inertial>
      <visual name="jetson_visual">
        <geometry>
          <mesh>
            <scale>1 1 1</scale>
            <uri>model://s500/meshes/jetson_link.STL</uri>
          </mesh>
        </geometry>
      </visual>
      <collision name='jetson_collision'>
        <geometry>
          <mesh>
            <scale>1 1 1</scale>
            <uri>model://s500/meshes/jetson_link.STL</uri>
          </mesh>
        </geometry>
      </collision>
    </link>
    <joint name='rotor1_joint' type='revolute'>
      <pose relative_to='base_link'>0.16254 -0.16286 0.081323 0 -0 1.5708</pose>
      <parent>base_link</parent>
      <child>rotor1_link</child>
      <axis>
        <xyz>0.073913 0.073913 0.99452</xyz>
        <limit>
          <lower>-1e+16</lower>
          <upper>1e+16</upper>
        </limit>
        <dynamics>
          <spring_reference>0</spring_reference>
          <spring_stiffness>0</spring_stiffness>
        </dynamics>
      </axis>
    </joint>
    <link name='rotor1_link'>
      <pose relative_to='rotor1_joint'>0 0 0 0 -0 0</pose>
      <inertial>
        <pose>-0.001201 -0.001201 -0.016157 0 -0 0</pose>
        <mass>0.136</mass>
        <inertia>
          <ixx>9.75e-07</ixx>
          <ixy>0</ixy>
          <ixz>0</ixz>
          <iyy>0.000273104</iyy>
          <iyz>0</iyz>
          <izz>0.000274004</izz>
        </inertia>
      </inertial>
      <collision name='rotor1_link_collision'>
        <pose>0 0 0 0 -0 0</pose>
        <geometry>
          <mesh>
            <scale>1 1 1</scale>
            <uri>model://s500/meshes/rotor1_link.STL</uri>
          </mesh>
        </geometry>
      </collision>
      <visual name='rotor1_link_visual'>
        <pose>0 0 0 0 -0 0</pose>
        <geometry>
          <mesh>
            <scale>1 1 1</scale>
            <uri>model://s500/meshes/rotor1_link.STL</uri>
          </mesh>
        </geometry>
      </visual>
    </link>
    <joint name='rotor2_joint' type='revolute'>
      <pose relative_to='base_link'>-0.16255 0.16223 0.081323 0 -0 1.5708</pose>
      <parent>base_link</parent>
      <child>rotor2_link</child>
      <axis>
        <xyz>-0.073913 -0.073913 0.99452</xyz>
        <limit>
          <lower>-1e+16</lower>
          <upper>1e+16</upper>
        </limit>
        <dynamics>
          <spring_reference>0</spring_reference>
          <spring_stiffness>0</spring_stiffness>
        </dynamics>
      </axis>
    </joint>
    <link name='rotor2_link'>
      <pose relative_to='rotor2_joint'>0 0 0 0 -0 0</pose>
      <inertial>
        <pose>0.001201 0.001201 -0.016157 0 -0 0</pose>
        <mass>0.136</mass>
        <inertia>
          <ixx>9.75e-07</ixx>
          <ixy>0</ixy>
          <ixz>0</ixz>
          <iyy>0.000273104</iyy>
          <iyz>0</iyz>
          <izz>0.000274004</izz>
        </inertia>
      </inertial>
      <collision name='rotor2_link_collision'>
        <pose>0 0 0 0 -0 0</pose>
        <geometry>
          <mesh>
            <scale>1 1 1</scale>
            <uri>model://s500/meshes/rotor2_link.STL</uri>
          </mesh>
        </geometry>
      </collision>
      <visual name='rotor2_link_visual'>
        <pose>0 0 0 0 -0 0</pose>
        <geometry>
          <mesh>
            <scale>1 1 1</scale>
            <uri>model://s500/meshes/rotor2_link.STL</uri>
          </mesh>
        </geometry>
      </visual>
    </link>
    <joint name='rotor3_joint' type='revolute'>
      <pose relative_to='base_link'>0.16254 0.16223 0.081323 0 -0 1.5708</pose>
      <parent>base_link</parent>
      <child>rotor3_link</child>
      <axis>
        <xyz>-0.073913 0.073913 0.99452</xyz>
        <limit>
          <lower>-1e+16</lower>
          <upper>1e+16</upper>
        </limit>
        <dynamics>
          <spring_reference>0</spring_reference>
          <spring_stiffness>0</spring_stiffness>
        </dynamics>
      </axis>
    </joint>
    <link name='rotor3_link'>
      <pose relative_to='rotor3_joint'>0 0 0 0 -0 0</pose>
      <inertial>
        <pose>0.001381 -0.001381 -0.018584 0 -0 0</pose>
        <mass>0.136</mass>
        <inertia>
          <ixx>9.75e-07</ixx>
          <ixy>0</ixy>
          <ixz>0</ixz>
          <iyy>0.000273104</iyy>
          <iyz>0</iyz>
          <izz>0.000274004</izz>
        </inertia>
      </inertial>
      <collision name='rotor3_link_collision'>
        <pose>0 0 0 0 -0 0</pose>
        <geometry>
          <mesh>
            <scale>1 1 1</scale>
            <uri>model://s500/meshes/rotor3_link.STL</uri>
          </mesh>
        </geometry>
      </collision>
      <visual name='rotor3_link_visual'>
        <pose>0 0 0 0 -0 0</pose>
        <geometry>
          <mesh>
            <scale>1 1 1</scale>
            <uri>model://s500/meshes/rotor3_link.STL</uri>
          </mesh>
        </geometry>
      </visual>
    </link>
    <joint name='rotor4_joint' type='revolute'>
      <pose relative_to='base_link'>-0.16255 -0.16286 0.081323 0 -0 1.5708</pose>
      <parent>base_link</parent>
      <child>rotor4_link</child>
      <axis>
        <xyz>0.073913 -0.073913 0.99452</xyz>
        <limit>
          <lower>-1e+16</lower>
          <upper>1e+16</upper>
        </limit>
        <dynamics>
          <spring_reference>0</spring_reference>
          <spring_stiffness>0</spring_stiffness>
        </dynamics>
      </axis>
    </joint>
    <link name='rotor4_link'>
      <pose relative_to='rotor4_joint'>0 0 0 0 -0 0</pose>
      <inertial>
        <pose>-0.001381 0.001381 -0.018584 0 -0 0</pose>
        <mass>0.136</mass>
        <inertia>
          <ixx>9.75e-07</ixx>
          <ixy>0</ixy>
          <ixz>0</ixz>
          <iyy>0.000273104</iyy>
          <iyz>0</iyz>
          <izz>0.000274004</izz>
        </inertia>
      </inertial>
      <collision name='rotor4_link_collision'>
        <pose>0 0 0 0 -0 0</pose>
        <geometry>
          <mesh>
            <scale>1 1 1</scale>
            <uri>model://s500/meshes/rotor4_link.STL</uri>
          </mesh>
        </geometry>
      </collision>
      <visual name='rotor4_link_visual'>
        <pose>0 0 0 0 -0 0</pose>
        <geometry>
          <mesh>
            <scale>1 1 1</scale>
            <uri>model://s500/meshes/rotor4_link.STL</uri>
          </mesh>
        </geometry>
      </visual>
    </link> 
    <!-- imu link and joints-->
    <link name='/imu_link'>
      <pose>0 0 0.01 0 0 0</pose>
      <inertial>
        <pose>0 0 0 0 0 0</pose>
        <mass>0.015</mass>
        <inertia>
          <ixx>1e-05</ixx>
          <ixy>0</ixy>
          <ixz>0</ixz>
          <iyy>1e-05</iyy>
          <iyz>0</iyz>
          <izz>1e-05</izz>
        </inertia>
      </inertial>
    </link>
    <joint name='/imu_joint' type='revolute'>
      <child>/imu_link</child>
      <parent>base_link</parent>
      <axis>
        <xyz>1 0 0</xyz>
        <limit>
          <lower>0</lower>
          <upper>0</upper>
          <effort>0</effort>
          <velocity>0</velocity>
        </limit>
        <dynamics>
          <spring_reference>0</spring_reference>
          <spring_stiffness>0</spring_stiffness>
        </dynamics>
        <use_parent_model_frame>1</use_parent_model_frame>
      </axis>
    </joint>
    <!-- Gps link and joints-->
    <include>
      <uri>model://gps</uri>
      <pose>-0.1 0 0.18 0 0 0</pose>
      <name>gps0</name>
    </include>
    <joint name='gps0_joint' type='fixed'>
      <child>gps0::link</child>
      <parent>base_link</parent>
    </joint>
    <!-- plugins-->
    <plugin name='rosbag' filename='libgazebo_multirotor_base_plugin.so'>
      <robotNamespace/>
      <linkName>base_link</linkName>
      <rotorVelocitySlowdownSim>10</rotorVelocitySlowdownSim>
    </plugin>
    <plugin name='motor1' filename='libgazebo_motor_model.so'>
      <robotNamespace/>
      <jointName>rotor1_joint</jointName>
      <linkName>rotor1_link</linkName>
      <turningDirection>ccw</turningDirection>
      <timeConstantUp>0.0125</timeConstantUp>
      <timeConstantDown>0.025</timeConstantDown>
      <maxRotVelocity>1477</maxRotVelocity>
      <motorConstant>8.09e-06</motorConstant>
      <momentConstant>0.0157829</momentConstant>
      <commandSubTopic>/gazebo/command/motor_speed</commandSubTopic>
      <motorNumber>0</motorNumber>
      <rotorDragCoefficient>0.00009541702789</rotorDragCoefficient>
      <rollingMomentCoefficient>1e-06</rollingMomentCoefficient>
      <motorSpeedPubTopic>/motor_speed/0</motorSpeedPubTopic>
      <rotorVelocitySlowdownSim>10</rotorVelocitySlowdownSim>
    </plugin>
    <plugin name='motor2' filename='libgazebo_motor_model.so'>
      <robotNamespace/>
      <jointName>rotor2_joint</jointName>
      <linkName>rotor2_link</linkName>
      <turningDirection>ccw</turningDirection>
      <timeConstantUp>0.0125</timeConstantUp>
      <timeConstantDown>0.025</timeConstantDown>
      <maxRotVelocity>1477</maxRotVelocity>
      <motorConstant>8.09e-06</motorConstant>
      <momentConstant>0.0157829</momentConstant>
      <commandSubTopic>/gazebo/command/motor_speed</commandSubTopic>
      <motorNumber>1</motorNumber>
      <rotorDragCoefficient>0.00009541702789</rotorDragCoefficient>
      <rollingMomentCoefficient>1e-06</rollingMomentCoefficient>
      <motorSpeedPubTopic>/motor_speed/1</motorSpeedPubTopic>
      <rotorVelocitySlowdownSim>10</rotorVelocitySlowdownSim>
    </plugin>
    <plugin name='motor3' filename='libgazebo_motor_model.so'>
      <robotNamespace/>
      <jointName>rotor3_joint</jointName>
      <linkName>rotor3_link</linkName>
      <turningDirection>cw</turningDirection>
      <timeConstantUp>0.0125</timeConstantUp>
      <timeConstantDown>0.025</timeConstantDown>
      <maxRotVelocity>1477</maxRotVelocity>
      <motorConstant>8.09e-06</motorConstant>
      <momentConstant>0.0157829</momentConstant>
      <commandSubTopic>/gazebo/command/motor_speed</commandSubTopic>
      <motorNumber>2</motorNumber>
      <rotorDragCoefficient>0.00009541702789</rotorDragCoefficient>
      <rollingMomentCoefficient>1e-06</rollingMomentCoefficient>
      <motorSpeedPubTopic>/motor_speed/2</motorSpeedPubTopic>
      <rotorVelocitySlowdownSim>10</rotorVelocitySlowdownSim>
    </plugin>
    <plugin name='motor4' filename='libgazebo_motor_model.so'>
      <robotNamespace/>
      <jointName>rotor4_joint</jointName>
      <linkName>rotor4_link</linkName>
      <turningDirection>cw</turningDirection>
      <timeConstantUp>0.0125</timeConstantUp>
      <timeConstantDown>0.025</timeConstantDown>
      <maxRotVelocity>1477</maxRotVelocity>
      <motorConstant>8.09e-06</motorConstant>
      <momentConstant>0.0157829</momentConstant>
      <commandSubTopic>/gazebo/command/motor_speed</commandSubTopic>
      <motorNumber>3</motorNumber>
      <rotorDragCoefficient>0.00009541702789</rotorDragCoefficient>
      <rollingMomentCoefficient>1e-06</rollingMomentCoefficient>
      <motorSpeedPubTopic>/motor_speed/3</motorSpeedPubTopic>
      <rotorVelocitySlowdownSim>10</rotorVelocitySlowdownSim>
    </plugin>
    <plugin name='groundtruth_plugin' filename='libgazebo_groundtruth_plugin.so'>
      <robotNamespace/>
    </plugin>
    <plugin name='magnetometer_plugin' filename='libgazebo_magnetometer_plugin.so'>
      <robotNamespace/>
      <pubRate>100</pubRate>
      <noiseDensity>0.0004</noiseDensity>
      <randomWalk>6.4e-06</randomWalk>
      <biasCorrelationTime>600</biasCorrelationTime>
      <magTopic>/mag</magTopic>
    </plugin>
    <plugin name='barometer_plugin' filename='libgazebo_barometer_plugin.so'>
      <robotNamespace/>
      <pubRate>50</pubRate>
      <baroTopic>/baro</baroTopic>
      <baroDriftPaPerSec>0</baroDriftPaPerSec>
    </plugin>
    <plugin name='mavlink_interface' filename='libgazebo_mavlink_interface.so'>
      <robotNamespace></robotNamespace>
      <imuSubTopic>/imu</imuSubTopic>
      <magSubTopic>/mag</magSubTopic>
      <baroSubTopic>/baro</baroSubTopic>
      <mavlink_addr>INADDR_ANY</mavlink_addr>
      <mavlink_tcp_port>4560</mavlink_tcp_port>
      <mavlink_udp_port>14560</mavlink_udp_port>
      <serialEnabled>0</serialEnabled>
      <serialDevice>/dev/ttyACM0</serialDevice>
      <baudRate>921600</baudRate>
      <qgc_addr>INADDR_ANY</qgc_addr>
      <qgc_udp_port>14550</qgc_udp_port>
      <sdk_addr>INADDR_ANY</sdk_addr>
      <sdk_udp_port>14540</sdk_udp_port>
      <hil_mode>0</hil_mode>
      <hil_state_level>false</hil_state_level>
      <enable_lockstep>true</enable_lockstep>
      <use_tcp>true</use_tcp>
      <motorSpeedCommandPubTopic>/gazebo/command/motor_speed</motorSpeedCommandPubTopic>
      <control_channels>
        <channel name="rotor0">
          <input_index>0</input_index>
          <input_offset>0</input_offset>
          <input_scaling>1500</input_scaling>
          <zero_position_disarmed>0</zero_position_disarmed>
          <zero_position_armed>100</zero_position_armed>
          <joint_control_type>velocity</joint_control_type>
        </channel>
        <channel name="rotor1">
          <input_index>1</input_index>
          <input_offset>0</input_offset>
          <input_scaling>1500</input_scaling>
          <zero_position_disarmed>0</zero_position_disarmed>
          <zero_position_armed>100</zero_position_armed>
          <joint_control_type>velocity</joint_control_type>
        </channel>
        <channel name="rotor2">
          <input_index>2</input_index>
          <input_offset>0</input_offset>
          <input_scaling>1500</input_scaling>
          <zero_position_disarmed>0</zero_position_disarmed>
          <zero_position_armed>100</zero_position_armed>
          <joint_control_type>velocity</joint_control_type>
        </channel>
        <channel name="rotor3">
          <input_index>3</input_index>
          <input_offset>0</input_offset>
          <input_scaling>1500</input_scaling>
          <zero_position_disarmed>0</zero_position_disarmed>
          <zero_position_armed>100</zero_position_armed>
          <joint_control_type>velocity</joint_control_type>
        </channel>
      </control_channels>
    </plugin>
    <static>0</static>
    <plugin name='gazebo_imu_plugin' filename='libgazebo_imu_plugin.so'>
      <robotNamespace></robotNamespace>
      <linkName>/imu_link</linkName>
      <imuTopic>/imu</imuTopic>
      <gyroscopeNoiseDensity>0.0003394</gyroscopeNoiseDensity>
      <gyroscopeRandomWalk>3.8785e-05</gyroscopeRandomWalk>
      <gyroscopeBiasCorrelationTime>1000.0</gyroscopeBiasCorrelationTime>
      <gyroscopeTurnOnBiasSigma>0.0087</gyroscopeTurnOnBiasSigma>
      <accelerometerNoiseDensity>0.004</accelerometerNoiseDensity>
      <accelerometerRandomWalk>0.006</accelerometerRandomWalk>
      <accelerometerBiasCorrelationTime>300.0</accelerometerBiasCorrelationTime>
      <accelerometerTurnOnBiasSigma>0.196</accelerometerTurnOnBiasSigma>
    </plugin>

  </model>
</sdf>